Workbook

Sheet 学年度总表
A1: 年级排名 | B1: 专业排名 | C1: 专业 | D1: 班级 | E1: 学号 | F1: 姓名 | G1: 大一上 | K1: 大一下 | O1: 学年总分 | P1: 奖学金 | Q1: 备注
G2: 品德总分 | H2: 学业总分 | I2: 文体总分 | J2: 综测总分 | K2: 品德总分 | L2: 学业总分 | M2: 文体总分 | N2: 综测总分
A3: =COUNTIFS($C$3:$C$1025,"<>大数据",$O$3:$O$1025,">"&O3)+1 -> 1 | B3: =COUNTIFS($C$3:$C$1025,C3,$O$3:$O$1025,">"&O3)+1 -> 1 | C3: 网工 | D3: 网工15班 | E3: 250451518 | F3: 单禹霖 | G3: 13.5 | H3: 69.67 | I3: 7.1 | J3: =ROUND(SUM(G3:I3),2) -> 90.27 | K3: 13 | L3: 68.43 | M3: 9 | N3: =ROUND(SUM(K3:M3),2) -> 90.43 | O3: =ROUND(SUM(J3,N3),2) -> 180.7 | P3: 国奖
A4: =COUNTIFS($C$3:$C$1025,"<>大数据",$O$3:$O$1025,">"&O4)+1 -> 2 | B4: =COUNTIFS($C$3:$C$1025,C4,$O$3:$O$1025,">"&O4)+1 -> 1 | C4: 软工 | D4: 软工14班 | E4: 250451433 | F4: 王奕茗 | G4: 9.8 | H4: 72.02 | I4: 5.1 | J4: =ROUND(SUM(G4:I4),2) -> 86.92 | K4: 11.3 | L4: 73.5 | M4: 8.05 | N4: =ROUND(SUM(K4:M4),2) -> 92.85 | O4: =ROUND(SUM(J4,N4),2) -> 179.77 | P4: 国奖
A5: =COUNTIFS($C$3:$C$1025,"<>大数据",$O$3:$O$1025,">"&O5)+1 -> 3 | B5: =COUNTIFS($C$3:$C$1025,C5,$O$3:$O$1025,">"&O5)+1 -> 1 | C5: 计科 | D5: 计科二班 | E5: 250450215 | F5: 薛继来 | G5: 10.8 | H5: 73.066667 | I5: 4.2 | J5: =ROUND(SUM(G5:I5),2) -> 88.07 | K5: 10.8 | L5: 74.71 | M5: 5.7 | N5: =ROUND(SUM(K5:M5),2) -> 91.21 | O5: =ROUND(SUM(J5,N5),2) -> 179.28 | P5: 省奖
A6: =COUNTIFS($C$3:$C$1025,"<>大数据",$O$3:$O$1025,">"&O6)+1 -> 4 | B6: =COUNTIFS($C$3:$C$1025,C6,$O$3:$O$1025,">"&O6)+1 -> 2 | C6: 软工 | D6: 软工12班 | E6: 250451226 | F6: 刘航绮 | G6: 12.5 | H6: 69.19 | I6: 6.9 | J6: =ROUND(SUM(G6:I6),2) -> 88.59 | K6: 11 | L6: 70.12 | M6: 8.5 | N6: =ROUND(SUM(K6:M6),2) -> 89.62 | O6: =ROUND(SUM(J6,N6),2) -> 178.21 | P6: 省奖
A7: =COUNTIFS($C$3:$C$1025,"<>大数据",$O$3:$O$1025,">"&O7)+1 -> 5 | B7: =COUNTIFS($C$3:$C$1025,C7,$O$3:$O$1025,">"&O7)+1 -> 3 | C7: 软工 | D7: 软工9班 | E7: 250450916 | F7: 夏艺洋 | G7: 10.3 | H7: 75 | I7: 5.1 | J7: =ROUND(SUM(G7:I7),2) -> 90.4 | K7: 10.8 | L7: 70.45 | M7: 6.5 | N7: =ROUND(SUM(K7:M7),2) -> 87.75 | O7: =ROUND(SUM(J7,N7),2) -> 178.15 | P7: 校一等
A8: =COUNTIFS($C$3:$C$1025,"<>大数据",$O$3:$O$1025,">"&O8)+1 -> 6 | B8: =COUNTIFS($C$3:$C$1025,C8,$O$3:$O$1025,">"&O8)+1 -> 4 | C8: 软工 | D8: 软工13班 | E8: 250451316 | F8: 孙远骐 | G8: 10.6 | H8: 72.84 | I8: 5.2 | J8: =ROUND(SUM(G8:I8),2) -> 88.64 | K8: 10.8 | L8: 67.92 | M8: 6.85 | N8: =ROUND(SUM(K8:M8),2) -> 85.57 | O8: =ROUND(SUM(J8,N8),2) -> 174.21 | P8: 校一等
A9: =COUNTIFS($C$3:$C$1025,"<>大数据",$O$3:$O$1025,">"&O9)+1 -> 7 | B9: =COUNTIFS($C$3:$C$1025,C9,$O$3:$O$1025,">"&O9)+1 -> 2 | C9: 网工 | D9: 网工16班 | E9: 250451631 | F9: 李辰析 | G9: 11.4 | H9: 68.99 | I9: 6.4 | J9: =ROUND(SUM(G9:I9),2) -> 86.79 | K9: 9.8 | L9: 69.46 | M9: 7.9 | N9: =ROUND(SUM(K9:M9),2) -> 87.16 | O9: =ROUND(SUM(J9,N9),2) -> 173.95 | P9: 校一等
A10: =COUNTIFS($C$3:$C$1025,"<>大数据",$O$3:$O$1025,">"&O10)+1 -> 8 | B10: =COUNTIFS($C$3:$C$1025,C10,$O$3:$O$1025,">"&O10)+1 -> 5 | C10: 软工 | D10: 软工6班 | E10: 250450614 | F10: 陈韵竹 | G10: 11.6 | H10: 73.690909 | I10: 3.5 | J10: =ROUND(SUM(G10:I10),2) -> 88.79 | K10: 9.8 | L10: 70.43 | M10: 4.9 | N10: =ROUND(SUM(K10:M10),2) -> 85.13 | O10: =ROUND(SUM(J10,N10),2) -> 173.92 | P10: 校一等
A11: =COUNTIFS($C$3:$C$1025,"<>大数据",$O$3:$O$1025,">"&O11)+1 -> 9 | B11: =COUNTIFS($C$3:$C$1025,C11,$O$3:$O$1025,">"&O11)+1 -> 1 | C11: 信管 | D11: 信管26班 | E11: 250452618 | F11: 刘嘉雯 | G11: 10.3 | H11: 72 | I11: 3.2 | J11: =ROUND(SUM(G11:I11),2) -> 85.5 | K11: 9.8 | L11: 70.95 | M11: 7.05 | N11: =ROUND(SUM(K11:M11),2) -> 87.8 | O11: =ROUND(SUM(J11,N11),2) -> 173.3 | P11: 校一等
A12: =COUNTIFS($C$3:$C$1025,"<>大数据",$O$3:$O$1025,">"&O12)+1 -> 10 | B12: =COUNTIFS($C$3:$C$1025,C12,$O$3:$O$1025,">"&O12)+1 -> 2 | C12: 计科 | D12: 计科一班 | E12: 250450119 | F12: 胡天淼 | G12: 12 | H12: 69.304878 | I12: 3.6 | J12: =ROUND(SUM(G12:I12),2) -> 84.9 | K12: 12 | L12: 70.13 | M12: 4.3 | N12: =ROUND(SUM(K12:M12),2) -> 86.43 | O12: =ROUND(SUM(J12,N12),2) -> 171.33 | P12: 校一等
A13: =COUNTIFS($C$3:$C$1025,"<>大数据",$O$3:$O$1025,">"&O13)+1 -> 11 | B13: =COUNTIFS($C$3:$C$1025,C13,$O$3:$O$1025,">"&O13)+1 -> 3 | C13: 计科 | D13: 计科一班 | E13: 250450123 | F13: 佟奕辰 | G13: 10.3 | H13: 67.902439 | I13: 4.7 | J13: =ROUND(SUM(G13:I13),2) -> 82.9 | K13: 11.3 | L13: 70.65 | M13: 6.4 | N13: =ROUND(SUM(K13:M13),2) -> 88.35 | O13: =ROUND(SUM(J13,N13),2) -> 171.25 | P13: 校一等
A14: =COUNTIFS($C$3:$C$1025,"<>大数据",$O$3:$O$1025,">"&O14)+1 -> 12 | B14: =COUNTIFS($C$3:$C$1025,C14,$O$3:$O$1025,">"&O14)+1 -> 2 | C14: 信管 | D14: 信管25班 | E14: 250452517 | F14: 赵春乔 | G14: 10.8 | H14: 69.71 | I14: 4.2 | J14: =ROUND(SUM(G14:I14),2) -> 84.71 | K14: 9.8 | L14: 68.58 | M14: 8 | N14: =ROUND(SUM(K14:M14),2) -> 86.38 | O14: =ROUND(SUM(J14,N14),2) -> 171.09 | P14: 校一等 | Q14: 转入商学院 财管
A15: =COUNTIFS($C$3:$C$1025,"<>大数据",$O$3:$O$1025,">"&O15)+1 -> 13 | B15: =COUNTIFS($C$3:$C$1025,C15,$O$3:$O$1025,">"&O15)+1 -> 4 | C15: 计科 | D15: 计科四班 | E15: 250450414 | F15: 迟钰莹 | G15: 10.8 | H15: 67.633333 | I15: 5.5 | J15: =ROUND(SUM(G15:I15),2) -> 83.93 | K15: 10 | L15: 71.75 | M15: 5.4 | N15: =ROUND(SUM(K15:M15),2) -> 87.15 | O15: =ROUND(SUM(J15,N15),2) -> 171.08 | P15: 校一等
A16: =COUNTIFS($C$3:$C$1025,"<>大数据",$O$3:$O$1025,">"&O16)+1 -> 14 | B16: =COUNTIFS($C$3:$C$1025,C16,$O$3:$O$1025,">"&O16)+1 -> 3 | C16: 信管 | D16: 信管26班 | E16: 250452627 | F16: 张舒涵 | G16: 11.3 | H16: 71.16 | I16: 4.7 | J16: =ROUND(SUM(G16:I16),2) -> 87.16 | K16: 9.8 | L16: 68.54 | M16: 5.5 | N16: =ROUND(SUM(K16:M16),2) -> 83.84 | O16: =ROUND(SUM(J16,N16),2) -> 171 | P16: 校一等
A17: =COUNTIFS($C$3:$C$1025,"<>大数据",$O$3:$O$1025,">"&O17)+1 -> 15 | B17: =COUNTIFS($C$3:$C$1025,C17,$O$3:$O$1025,">"&O17)+1 -> 6 | C17: 软工 | D17: 软工14班 | E17: 250451405 | F17: 周梓锐 | G17: 11 | H17: 73.14 | I17: 3.8 | J17: =ROUND(SUM(G17:I17),2) -> 87.94 | K17: 10 | L17: 68.5 | M17: 4 | N17: =ROUND(SUM(K17:M17),2) -> 82.5 | O17: =ROUND(SUM(J17,N17),2) -> 170.44 | P17: 校一等
A18: =COUNTIFS($C$3:$C$1025,"<>大数据",$O$3:$O$1025,">"&O18)+1 -> 16 | B18: =COUNTIFS($C$3:$C$1025,C18,$O$3:$O$1025,">"&O18)+1 -> 7 | C18: 软工 | D18: 软工7班 | E18: 250450721 | F18: 吴悠 | G18: 11.1 | H18: 69.24 | I18: 4.9 | J18: =ROUND(SUM(G18:I18),2) -> 85.24 | K18: 9.8 | L18: 68.08 | M18: 7.2 | N18: =ROUND(SUM(K18:M18),2) -> 85.08 | O18: =ROUND(SUM(J18,N18),2) -> 170.32 | P18: 校一等
A19: =COUNTIFS($C$3:$C$1025,"<>大数据",$O$3:$O$1025,">"&O19)+1 -> 17 | B19: =COUNTIFS($C$3:$C$1025,C19,$O$3:$O$1025,">"&O19)+1 -> 8 | C19: 软工 | D19: 软工7班 | E19: 250450708 | F19: 尹彦茜 | G19: 10.8 | H19: 73.7 | I19: 4 | J19: =ROUND(SUM(G19:I19),2) -> 88.5 | K19: 7.3 | L19: 70.23 | M19: 4 | N19: =ROUND(SUM(K19:M19),2) -> 81.53 | O19: =ROUND(SUM(J19,N19),2) -> 170.03 | P19: 校一等
A20: =COUNTIFS($C$3:$C$1025,"<>大数据",$O$3:$O$1025,">"&O20)+1 -> 18 | B20: =COUNTIFS($C$3:$C$1025,C20,$O$3:$O$1025,">"&O20)+1 -> 3 | C20: 网工 | D20: 网工16班 | E20: 250451615 | F20: 吕静怡 | G20: 9.8 | H20: 69.88 | I20: 5.2 | J20: =ROUND(SUM(G20:I20),2) -> 84.88 | K20: 9.8 | L20: 67.08 | M20: 7.5 | N20: =ROUND(SUM(K20:M20),2) -> 84.38 | O20: =ROUND(SUM(J20,N20),2) -> 169.26 | P20: 国励
A21: =COUNTIFS($C$3:$C$1025,"<>大数据",$O$3:$O$1025,">"&O21)+1 -> 19 | B21: =COUNTIFS($C$3:$C$1025,C21,$O$3:$O$1025,">"&O21)+1 -> 4 | C21: 信管 | D21: 信管22班 | E21: 250452220 | F21: 贺中泽 | G21: 10.8 | H21: 71.33 | I21: 4 | J21: =ROUND(SUM(G21:I21),2) -> 86.13 | K21: 10.8 | L21: 66.95 | M21: 5.35 | N21: =ROUND(SUM(K21:M21),2) -> 83.1 | O21: =ROUND(SUM(J21,N21),2) -> 169.23 | P21: 校一等
A22: =COUNTIFS($C$3:$C$1025,"<>大数据",$O$3:$O$1025,">"&O22)+1 -> 20 | B22: =COUNTIFS($C$3:$C$1025,C22,$O$3:$O$1025,">"&O22)+1 -> 5 | C22: 计科 | D22: 计科三班 | E22: 250450315 | F22: 程俊杰 | G22: 9.8 | H22: 71.232558 | I22: 5.2 | J22: =ROUND(SUM(G22:I22),2) -> 86.23 | K22: 9 | L22: 68.5 | M22: 5.2 | N22: =ROUND(SUM(K22:M22),2) -> 82.7 | O22: =ROUND(SUM(J22,N22),2) -> 168.93 | P22: 校二等
A23: =COUNTIFS($C$3:$C$1025,"<>大数据",$O$3:$O$1025,">"&O23)+1 -> 21 | B23: =COUNTIFS($C$3:$C$1025,C23,$O$3:$O$1025,">"&O23)+1 -> 4 | C23: 网工 | D23: 网工15班 | E23: 250451527 | F23: 沈乃鑫 | G23: 9.8 | H23: 67 | I23: 5.1 | J23: =ROUND(SUM(G23:I23),2) -> 81.9 | K23: 9.8 | L23: 70.02 | M23: 6.9 | N23: =ROUND(SUM(K23:M23),2) -> 86.72 | O23: =ROUND(SUM(J23,N23),2) -> 168.62 | P23: 校一等
A24: =COUNTIFS($C$3:$C$1025,"<>大数据",$O$3:$O$1025,">"&O24)+1 -> 22 | B24: =COUNTIFS($C$3:$C$1025,C24,$O$3:$O$1025,">"&O24)+1 -> 9 | C24: 软工 | D24: 软工8班 | E24: 250450825 | F24: 万雨 | G24: 11.3 | H24: 68.323529 | I24: 5.5 | J24: =ROUND(SUM(G24:I24),2) -> 85.12 | K24: 11 | L24: 67.22 | M24: 5.1 | N24: =ROUND(SUM(K24:M24),2) -> 83.32 | O24: =ROUND(SUM(J24,N24),2) -> 168.44 | P24: 校一等
A25: =COUNTIFS($C$3:$C$1025,"<>大数据",$O$3:$O$1025,">"&O25)+1 -> 23 | B25: =COUNTIFS($C$3:$C$1025,C25,$O$3:$O$1025,">"&O25)+1 -> 10 | C25: 软工 | D25: 软工14班 | E25: 250451401 | F25: 马艺方 | G25: 11.3 | H25: 69.77 | I25: 5.1 | J25: =ROUND(SUM(G25:I25),2) -> 86.17 | K25: 10.8 | L25: 66 | M25: 5.3 | N25: =ROUND(SUM(K25:M25),2) -> 82.1 | O25: =ROUND(SUM(J25,N25),2) -> 168.27 | P25: 校二等
A26: =COUNTIFS($C$3:$C$1025,"<>大数据",$O$3:$O$1025,">"&O26)+1 -> 24 | B26: =COUNTIFS($C$3:$C$1025,C26,$O$3:$O$1025,">"&O26)+1 -> 11 | C26: 软工 | D26: 软工13班 | E26: 250451324 | F26: 赵君昇 | G26: 10 | H26: 73.8 | I26: 4 | J26: =ROUND(SUM(G26:I26),2) -> 87.8 | K26: 10 | L26: 66.96 | M26: 3.5 | N26: =ROUND(SUM(K26:M26),2) -> 80.46 | O26: =ROUND(SUM(J26,N26),2) -> 168.26 | P26: 校二等
... A33: =COUNTIFS($C$3:$C$1025,"<>大数据",$O$3:$O$1025,">"&O33)+1 -> 31 | B33: =COUNTIFS($C$3:$C$1025,C33,$O$3:$O$1025,">"&O33)+1 -> 7 | C33: 信管 | D33: 信管24班 | E33: 250452426 | F33: 陈尔其 | G33: 9.8 | H33: 70.97 | I33: 5.3 | J33: =ROUND(SUM(G33:I33),2) -> 86.07 | K33: 9.8 | L33: 64.72 | M33: 5.8 | N33: =ROUND(SUM(K33:M33),2) -> 80.32 | O33: =ROUND(SUM(J33,N33),2) -> 166.39 | P33: 校一等
A34: =COUNTIFS($C$3:$C$1025,"<>大数据",$O$3:$O$1025,">"&O34)+1 -> 32 | B34: =COUNTIFS($C$3:$C$1025,C34,$O$3:$O$1025,">"&O34)+1 -> 8 | C34: 计科 | D34: 计科一班 | E34: 250450122 | F34: 张淅傲 | G34: 12.8 | H34: 66.533333 | I34: 5.8 | J34: =ROUND(SUM(G34:I34),2) -> 85.13 | K34: 11.3 | L34: 61.55 | M34: 8.4 | N34: =ROUND(SUM(K34:M34),2) -> 81.25 | O34: =ROUND(SUM(J34,N34),2) -> 166.38
A35: =COUNTIFS($C$3:$C$1025,"<>大数据",$O$3:$O$1025,">"&O35)+1 -> 33 | B35: =COUNTIFS($C$3:$C$1025,C35,$O$3:$O$1025,">"&O35)+1 -> 14 | C35: 软工 | D35: 软工12班 | E35: 250451212 | F35: 朱泓蓉 | G35: 12.8 | H35: 67.17 | I35: 5.5 | J35: =ROUND(SUM(G35:I35),2) -> 85.47 | K35: 11.3 | L35: 60.47 | M35: 9 | N35: =ROUND(SUM(K35:M35),2) -> 80.77 | O35: =ROUND(SUM(J35,N35),2) -> 166.24 | P35: 校二等
A36: =COUNTIFS($C$3:$C$1025,"<>大数据",$O$3:$O$1025,">"&O36)+1 -> 34 | B36: =COUNTIFS($C$3:$C$1025,C36,$O$3:$O$1025,">"&O36)+1 -> 8 | C36: 信管 | D36: 信管27班 | E36: 250452733 | F36: 杨众然 | G36: 9.8 | H36: 70.8 | I36: 3.2 | J36: =ROUND(SUM(G36:I36),2) -> 83.8 | K36: 9.8 | L36: 68.32 | M36: 4.2 | N36: =ROUND(SUM(K36:M36),2) -> 82.32 | O36: =ROUND(SUM(J36,N36),2) -> 166.12 | P36: 校二等
A37: =COUNTIFS($C$3:$C$1025,"<>大数据",$O$3:$O$1025,">"&O37)+1 -> 35 | B37: =COUNTIFS($C$3:$C$1025,C37,$O$3:$O$1025,">"&O37)+1 -> 5 | C37: 网工 | D37: 网工15班 | E37: 250451533 | F37: 赵一婷 | G37: 13 | H37: 64.38 | I37: 5.6 | J37: =ROUND(SUM(G37:I37),2) -> 82.98 | K37: 12 | L37: 62.04 | M37: 9 | N37: =ROUND(SUM(K37:M37),2) -> 83.04 | O37: =ROUND(SUM(J37,N37),2) -> 166.02 | P37: 校一等
A38: =COUNTIFS($C$3:$C$1025,"<>大数据",$O$3:$O$1025,">"&O38)+1 -> 36 | B38: =COUNTIFS($C$3:$C$1025,C38,$O$3:$O$1025,">"&O38)+1 -> 9 | C38: 信管 | D38: 信管21班 | E38: 250452124 | F38: 李瑞洋 | G38: 9.8 | H38: 70.14 | I38: 4.2 | J38: =ROUND(SUM(G38:I38),2) -> 84.14 | K38: 9.8 | L38: 67.27 | M38: 4.7 | N38: =ROUND(SUM(K38:M38),2) -> 81.77 | O38: =ROUND(SUM(J38,N38),2) -> 165.91 | P38: 校二等
A39: =COUNTIFS($C$3:$C$1025,"<>大数据",$O$3:$O$1025,">"&O39)+1 -> 37 | B39: =COUNTIFS($C$3:$C$1025,C39,$O$3:$O$1025,">"&O39)+1 -> 15 | C39: 软工 | D39: 软工11班 | E39: 250451103 | F39: 李沛庭 | G39: 11 | H39: 67.98 | I39: 5.2 | J39: =ROUND(SUM(G39:I39),2) -> 84.18 | K39: 10 | L39: 65.52 | M39: 6.2 | N39: =ROUND(SUM(K39:M39),2) -> 81.72 | O39: =ROUND(SUM(J39,N39),2) -> 165.9 | P39: 校二等
A40: =COUNTIFS($C$3:$C$1025,"<>大数据",$O$3:$O$1025,">"&O40)+1 -> 38 | B40: =COUNTIFS($C$3:$C$1025,C40,$O$3:$O$1025,">"&O40)+1 -> 10 | C40: 信管 | D40: 信管24班 | E40: 250452419 | F40: 刘一鸣 | G40: 9.8 | H40: 68.73 | I40: 4.9 | J40: =ROUND(SUM(G40:I40),2) -> 83.43 | K40: 9.8 | L40: 66.52 | M40: 6.1 | N40: =ROUND(SUM(K40:M40),2) -> 82.42 | O40: =ROUND(SUM(J40,N40),2) -> 165.85 | P40: 校二等
A41: =COUNTIFS($C$3:$C$1025,"<>大数据",$O$3:$O$1025,">"&O41)+1 -> 39 | B41: =COUNTIFS($C$3:$C$1025,C41,$O$3:$O$1025,">"&O41)+1 -> 11 | C41: 信管 | D41: 信管28班 | E41: 250452813 | F41: 高乃姬 | G41: 9.8 | H41: 71.86 | I41: 4.2 | J41: =ROUND(SUM(G41:I41),2) -> 85.86 | K41: 9.8 | L41: 64.76 | M41: 5.1 | N41: =ROUND(SUM(K41:M41),2) -> 79.66 | O41: =ROUND(SUM(J41,N41),2) -> 165.52 | P41: 校二等
A42: =COUNTIFS($C$3:$C$1025,"<>大数据",$O$3:$O$1025,">"&O42)+1 -> 40 | B42: =COUNTIFS($C$3:$C$1025,C42,$O$3:$O$1025,">"&O42)+1 -> 12 | C42: 信管 | D42: 信管25班 | E42: 250452531 | F42: 刘书语 | G42: 9.8 | H42: 72.19 | I42: 4.2 | J42: =ROUND(SUM(G42:I42),2) -> 86.19 | K42: 9.8 | L42: 65.05 | M42: 4 | N42: =ROUND(SUM(K42:M42),2) -> 78.85 | O42: =ROUND(SUM(J42,N42),2) -> 165.04 | P42: 校二等
A43: =COUNTIFS($C$3:$C$1025,"<>大数据",$O$3:$O$1025,">"&O43)+1 -> 41 | B43: =COUNTIFS($C$3:$C$1025,C43,$O$3:$O$1025,">"&O43)+1 -> 9 | C43: 计科 | D43: 计科一班 | E43: 250450124 | F43: 刘奕含 | G43: 10.8 | H43: 65.865854 | I43: 5 | J43: =ROUND(SUM(G43:I43),2) -> 81.67 | K43: 10.8 | L43: 66.24 | M43: 6.2 | N43: =ROUND(SUM(K43:M43),2) -> 83.24 | O43: =ROUND(SUM(J43,N43),2) -> 164.91 | P43: 校二等
A44: =COUNTIFS($C$3:$C$1025,"<>大数据",$O$3:$O$1025,">"&O44)+1 -> 42 | B44: =COUNTIFS($C$3:$C$1025,C44,$O$3:$O$1025,">"&O44)+1 -> 10 | C44: 计科 | D44: 计科三班 | E44: 250450323 | F44: 吕佳妮 | G44: 10.8 | H44: 69.170732 | I44: 4.5 | J44: =ROUND(SUM(G44:I44),2) -> 84.47 | K44: 9 | L44: 65.49 | M44: 5.9 | N44: =ROUND(SUM(K44:M44),2) -> 80.39 | O44: =ROUND(SUM(J44,N44),2) -> 164.86 | P44: 校三等
A45: =COUNTIFS($C$3:$C$1025,"<>大数据",$O$3:$O$1025,">"&O45)+1 -> 43 | B45: =COUNTIFS($C$3:$C$1025,C45,$O$3:$O$1025,">"&O45)+1 -> 16 | C45: 软工 | D45: 软工6班 | E45: 250450625 | F45: 佟欣恬 | G45: 11.8 | H45: 66.142857 | I45: 5.6 | J45: =ROUND(SUM(G45:I45),2) -> 83.54 | K45: 9.8 | L45: 63 | M45: 8.45 | N45: =ROUND(SUM(K45:M45),2) -> 81.25 | O45: =ROUND(SUM(J45,N45),2) -> 164.79 | P45: 校二等
A46: =COUNTIFS($C$3:$C$1025,"<>大数据",$O$3:$O$1025,">"&O46)+1 -> 44 | B46: =COUNTIFS($C$3:$C$1025,C46,$O$3:$O$1025,">"&O46)+1 -> 17 | C46: 软工 | D46: 软工13班 | E46: 250451302 | F46: 闻宣淇 | G46: 11 | H46: 71.28 | I46: 3.8 | J46: =ROUND(SUM(G46:I46),2) -> 86.08 | K46: 10 | L46: 64.01 | M46: 4.6 | N46: =ROUND(SUM(K46:M46),2) -> 78.61 | O46: =ROUND(SUM(J46,N46),2) -> 164.69 | P46: 校二等 | Q46: 转英语
...

Sheet 计科排名
A1: 年级排名 | B1: 专业排名 | C1: 专业 | D1: 班级 | E1: 学号 | F1: 姓名 | G1: 大一上 | K1: 大一下 | O1: 学年总分 | P1: 奖学金 | Q1: 备注
G2: 品德总分 | H2: 学业总分 | I2: 文体总分 | J2: 综测总分 | K2: 品德总分 | L2: 学业总分 | M2: 文体总分 | N2: 综测总分
A3: =IF(INDEX(学年度总表!$A$3:$A$1025,MATCH($E3,学年度总表!$E$3:$E$1025,0))="","",INDEX(学年度总表!$A$3:$A$1025,MATCH($E3,学年度总表!$E$3:$E$1025,0))) -> 3 | B3: =IF(INDEX(学年度总表!$B$3:$B$1025,MATCH($E3,学年度总表!$E$3:$E$1025,0))="","",INDEX(学年度总表!$B$3:$B$1025,MATCH($E3,学年度总表!$E$3:$E$1025,0))) -> 1 | C3: =IF(INDEX(学年度总表!$C$3:$C$1025,MATCH($E3,学年度总表!$E$3:$E$1025,0))="","",INDEX(学年度总表!$C$3:$C$1025,MATCH($E3,学年度总表!$E$3:$E$1025,0))) -> 计科 | D3: =IF(INDEX(学年度总表!$D$3:$D$1025,MATCH($E3,学年度总表!$E$3:$E$1025,0))="","",INDEX(学年度总表!$D$3:$D$1025,MATCH($E3,学年度总表!$E$3:$E$1025,0))) -> 计科二班 | E3: 250450215 | F3: =IF(INDEX(学年度总表!$F$3:$F$1025,MATCH($E3,学年度总表!$E$3:$E$1025,0))="","",INDEX(学年度总表!$F$3:$F$1025,MATCH($E3,学年度总表!$E$3:$E$1025,0))) -> 薛继来 | G3: =IF(INDEX(学年度总表!$G$3:$G$1025,MATCH($E3,学年度总表!$E$3:$E$1025,0))="","",INDEX(学年度总表!$G$3:$G$1025,MATCH($E3,学年度总表!$E$3:$E$1025,0))) -> 10.8 | H3: =IF(INDEX(学年度总表!$H$3:$H$1025,MATCH($E3,学年度总表!$E$3:$E$1025,0))="","",INDEX(学年度总表!$H$3:$H$1025,MATCH($E3,学年度总表!$E$3:$E$1025,0))) -> 73.066667 | I3: =IF(INDEX(学年度总表!$I$3:$I$1025,MATCH($E3,学年度总表!$E$3:$E$1025,0))="","",INDEX(学年度总表!$I$3:$I$1025,MATCH($E3,学年度总表!$E$3:$E$1025,0))) -> 4.2 | J3: =IF(INDEX(学年度总表!$J$3:$J$1025,MATCH($E3,学年度总表!$E$3:$E$1025,0))="","",INDEX(学年度总表!$J$3:$J$1025,MATCH($E3,学年度总表!$E$3:$E$1025,0))) -> 88.07 | K3: =IF(INDEX(学年度总表!$K$3:$K$1025,MATCH($E3,学年度总表!$E$3:$E$1025,0))="","",INDEX(学年度总表!$K$3:$K$1025,MATCH($E3,学年度总表!$E$3:$E$1025,0))) -> 10.8 | L3: =IF(INDEX(学年度总表!$L$3:$L$1025,MATCH($E3,学年度总表!$E$3:$E$1025,0))="","",INDEX(学年度总表!$L$3:$L$1025,MATCH($E3,学年度总表!$E$3:$E$1025,0))) -> 74.71 | M3: =IF(INDEX(学年度总表!$M$3:$M$1025,MATCH($E3,学年度总表!$E$3:$E$1025,0))="","",INDEX(学年度总表!$M$3:$M$1025,MATCH($E3,学年度总表!$E$3:$E$1025,0))) -> 5.7 | N3: =IF(INDEX(学年度总表!$N$3:$N$1025,MATCH($E3,学年度总表!$E$3:$E$1025,0))="","",INDEX(学年度总表!$N$3:$N$1025,MATCH($E3,学年度总表!$E$3:$E$1025,0))) -> 91.21 | O3: =IF(INDEX(学年度总表!$O$3:$O$1025,MATCH($E3,学年度总表!$E$3:$E$1025,0))="","",INDEX(学年度总表!$O$3:$O$1025,MATCH($E3,学年度总表!$E$3:$E$1025,0))) -> 179.28 | P3: =IF(INDEX(学年度总表!$P$3:$P$1025,MATCH($E3,学年度总表!$E$3:$E$1025,0))="","",INDEX(学年度总表!$P$3:$P$1025,MATCH($E3,学年度总表!$E$3:$E$1025,0))) -> 省奖 | Q3: =IF(INDEX(学年度总表!$Q$3:$Q$1025,MATCH($E3,学年度总表!$E$3:$E$1025,0))="","",INDEX(学年度总表!$Q$3:$Q$1025,MATCH($E3,学年度总表!$E$3:$E$1025,0)))
A4: =IF(INDEX(学年度总表!$A$3:$A$1025,MATCH($E4,学年度总表!$E$3:$E$1025,0))="","",INDEX(学年度总表!$A$3:$A$1025,MATCH($E4,学年度总表!$E$3:$E$1025,0))) -> 10 | B4: =IF(INDEX(学年度总表!$B$3:$B$1025,MATCH($E4,学年度总表!$E$3:$E$1025,0))="","",INDEX(学年度总表!$B$3:$B$1025,MATCH($E4,学年度总表!$E$3:$E$1025,0))) -> 2 | C4: =IF(INDEX(学年度总表!$C$3:$C$1025,MATCH($E4,学年度总表!$E$3:$E$1025,0))="","",INDEX(学年度总表!$C$3:$C$1025,MATCH($E4,学年度总表!$E$3:$E$1025,0))) -> 计科 | D4: =IF(INDEX(学年度总表!$D$3:$D$1025,MATCH($E4,学年度总表!$E$3:$E$1025,0))="","",INDEX(学年度总表!$D$3:$D$1025,MATCH($E4,学年度总表!$E$3:$E$1025,0))) -> 计科一班 | E4: 250450119 | F4: =IF(INDEX(学年度总表!$F$3:$F$1025,MATCH($E4,学年度总表!$E$3:$E$1025,0))="","",INDEX(学年度总表!$F$3:$F$1025,MATCH($E4,学年度总表!$E$3:$E$1025,0))) -> 胡天淼 | G4: =IF(INDEX(学年度总表!$G$3:$G$1025,MATCH($E4,学年度总表!$E$3:$E$1025,0))="","",INDEX(学年度总表!$G$3:$G$1025,MATCH($E4,学年度总表!$E$3:$E$1025,0))) -> 12 | H4: =IF(INDEX(学年度总表!$H$3:$H$1025,MATCH($E4,学年度总表!$E$3:$E$1025,0))="","",INDEX(学年度总表!$H$3:$H$1025,MATCH($E4,学年度总表!$E$3:$E$1025,0))) -> 69.304878 | I4: =IF(INDEX(学年度总表!$I$3:$I$1025,MATCH($E4,学年度总表!$E$3:$E$1025,0))="","",INDEX(学年度总表!$I$3:$I$1025,MATCH($E4,学年度总表!$E$3:$E$1025,0))) -> 3.6 | J4: =IF(INDEX(学年度总表!$J$3:$J$1025,MATCH($E4,学年度总表!$E$3:$E$1025,0))="","",INDEX(学年度总表!$J$3:$J$1025,MATCH($E4,学年度总表!$E$3:$E$1025,0))) -> 84.9 | K4: =IF(INDEX(学年度总表!$K$3:$K$1025,MATCH($E4,学年度总表!$E$3:$E$1025,0))="","",INDEX(学年度总表!$K$3:$K$1025,MATCH($E4,学年度总表!$E$3:$E$1025,0))) -> 12 | L4: =IF(INDEX(学年度总表!$L$3:$L$1025,MATCH($E4,学年度总表!$E$3:$E$1025,0))="","",INDEX(学年度总表!$L$3:$L$1025,MATCH($E4,学年度总表!$E$3:$E$1025,0))) -> 70.13 | M4: =IF(INDEX(学年度总表!$M$3:$M$1025,MATCH($E4,学年度总表!$E$3:$E$1025,0))="","",INDEX(学年度总表!$M$3:$M$1025,MATCH($E4,学年度总表!$E$3:$E$1025,0))) -> 4.3 | N4: =IF(INDEX(学年度总表!$N$3:$N$1025,MATCH($E4,学年度总表!$E$3:$E$1025,0))="","",INDEX(学年度总表!$N$3:$N$1025,MATCH($E4,学年度总表!$E$3:$E$1025,0))) -> 86.43 | O4: =IF(INDEX(学年度总表!$O$3:$O$1025,MATCH($E4,学年度总表!$E$3:$E$1025,0))="","",INDEX(学年度总表!$O$3:$O$1025,MATCH($E4,学年度总表!$E$3:$E$1025,0))) -> 171.33 | P4: =IF(INDEX(学年度总表!$P$3:$P$1025,MATCH($E4,学年度总表!$E$3:$E$1025,0))="","",INDEX(学年度总表!$P$3:$P$1025,MATCH($E4,学年度总表!$E$3:$E$1025,0))) -> 校一等 | Q4: =IF(INDEX(学年度总表!$Q$3:$Q$1025,MATCH($E4,学年度总表!$E$3:$E$1025,0))="","",INDEX(学年度总表!$Q$3:$Q$1025,MATCH($E4,学年度总表!$E$3:$E$1025,0)))
A5: =IF(INDEX(学年度总表!$A$3:$A$1025,MATCH($E5,学年度总表!$E$3:$E$1025,0))="","",INDEX(学年度总表!$A$3:$A$1025,MATCH($E5,学年度总表!$E$3:$E$1025,0))) -> 11 | B5: =IF(INDEX(学年度总表!$B$3:$B$1025,MATCH($E5,学年度总表!$E$3:$E$1025,0))="","",INDEX(学年度总表!$B$3:$B$1025,MATCH($E5,学年度总表!$E$3:$E$1025,0))) -> 3 | C5: =IF(INDEX(学年度总表!$C$3:$C$1025,MATCH($E5,学年度总表!$E$3:$E$1025,0))="","",INDEX(学年度总表!$C$3:$C$1025,MATCH($E5,学年度总表!$E$3:$E$1025,0))) -> 计科 | D5: =IF(INDEX(学年度总表!$D$3:$D$1025,MATCH($E5,学年度总表!$E$3:$E$1025,0))="","",INDEX(学年度总表!$D$3:$D$1025,MATCH($E5,学年度总表!$E$3:$E$1025,0))) -> 计科一班 | E5: 250450123 | F5: =IF(INDEX(学年度总表!$F$3:$F$1025,MATCH($E5,学年度总表!$E$3:$E$1025,0))="","",INDEX(学年度总表!$F$3:$F$1025,MATCH($E5,学年度总表!$E$3:$E$1025,0))) -> 佟奕辰 | G5: =IF(INDEX(学年度总表!$G$3:$G$1025,MATCH($E5,学年度总表!$E$3:$E$1025,0))="","",INDEX(学年度总表!$G$3:$G$1025,MATCH($E5,学年度总表!$E$3:$E$1025,0))) -> 10.3 | H5: =IF(INDEX(学年度总表!$H$3:$H$1025,MATCH($E5,学年度总表!$E$3:$E$1025,0))="","",INDEX(学年度总表!$H$3:$H$1025,MATCH($E5,学年度总表!$E$3:$E$1025,0))) -> 67.902439 | I5: =IF(INDEX(学年度总表!$I$3:$I$1025,MATCH($E5,学年度总表!$E$3:$E$1025,0))="","",INDEX(学年度总表!$I$3:$I$1025,MATCH($E5,学年度总表!$E$3:$E$1025,0))) -> 4.7 | J5: =IF(INDEX(学年度总表!$J$3:$J$1025,MATCH($E5,学年度总表!$E$3:$E$1025,0))="","",INDEX(学年度总表!$J$3:$J$1025,MATCH($E5,学年度总表!$E$3:$E$1025,0))) -> 82.9 | K5: =IF(INDEX(学年度总表!$K$3:$K$1025,MATCH($E5,学年度总表!$E$3:$E$1025,0))="","",INDEX(学年度总表!$K$3:$K$1025,MATCH($E5,学年度总表!$E$3:$E$1025,0))) -> 11.3 | L5: =IF(INDEX(学年度总表!$L$3:$L$1025,MATCH($E5,学年度总表!$E$3:$E$1025,0))="","",INDEX(学年度总表!$L$3:$L$1025,MATCH($E5,学年度总表!$E$3:$E$1025,0))) -> 70.65 | M5: =IF(INDEX(学年度总表!$M$3:$M$1025,MATCH($E5,学年度总表!$E$3:$E$1025,0))="","",INDEX(学年度总表!$M$3:$M$1025,MATCH($E5,学年度总表!$E$3:$E$1025,0))) -> 6.4 | N5: =IF(INDEX(学年度总表!$N$3:$N$1025,MATCH($E5,学年度总表!$E$3:$E$1025,0))="","",INDEX(学年度总表!$N$3:$N$1025,MATCH($E5,学年度总表!$E$3:$E$1025,0))) -> 88.35 | O5: =IF(INDEX(学年度总表!$O$3:$O$1025,MATCH($E5,学年度总表!$E$3:$E$1025,0))="","",INDEX(学年度总表!$O$3:$O$1025,MATCH($E5,学年度总表!$E$3:$E$1025,0))) -> 171.25 | P5: =IF(INDEX(学年度总表!$P$3:$P$1025,MATCH($E5,学年度总表!$E$3:$E$1025,0))="","",INDEX(学年度总表!$P$3:$P$1025,MATCH($E5,学年度总表!$E$3:$E$1025,0))) -> 校一等 | Q5: =IF(INDEX(学年度总表!$Q$3:$Q$1025,MATCH($E5,学年度总表!$E$3:$E$1025,0))="","",INDEX(学年度总表!$Q$3:$Q$1025,MATCH($E5,学年度总表!$E$3:$E$1025,0)))
A6: =IF(INDEX(学年度总表!$A$3:$A$1025,MATCH($E6,学年度总表!$E$3:$E$1025,0))="","",INDEX(学年度总表!$A$3:$A$1025,MATCH($E6,学年度总表!$E$3:$E$1025,0))) -> 13 | B6: =IF(INDEX(学年度总表!$B$3:$B$1025,MATCH($E6,学年度总表!$E$3:$E$1025,0))="","",INDEX(学年度总表!$B$3:$B$1025,MATCH($E6,学年度总表!$E$3:$E$1025,0))) -> 4 | C6: =IF(INDEX(学年度总表!$C$3:$C$1025,MATCH($E6,学年度总表!$E$3:$E$1025,0))="","",INDEX(学年度总表!$C$3:$C$1025,MATCH($E6,学年度总表!$E$3:$E$1025,0))) -> 计科 | D6: =IF(INDEX(学年度总表!$D$3:$D$1025,MATCH($E6,学年度总表!$E$3:$E$1025,0))="","",INDEX(学年度总表!$D$3:$D$1025,MATCH($E6,学年度总表!$E$3:$E$1025,0))) -> 计科四班 | E6: 250450414 | F6: =IF(INDEX(学年度总表!$F$3:$F$1025,MATCH($E6,学年度总表!$E$3:$E$1025,0))="","",INDEX(学年度总表!$F$3:$F$1025,MATCH($E6,学年度总表!$E$3:$E$1025,0))) -> 迟钰莹 | G6: =IF(INDEX(学年度总表!$G$3:$G$1025,MATCH($E6,学年度总表!$E$3:$E$1025,0))="","",INDEX(学年度总表!$G$3:$G$1025,MATCH($E6,学年度总表!$E$3:$E$1025,0))) -> 10.8 | H6: =IF(INDEX(学年度总表!$H$3:$H$1025,MATCH($E6,学年度总表!$E$3:$E$1025,0))="","",INDEX(学年度总表!$H$3:$H$1025,MATCH($E6,学年度总表!$E$3:$E$1025,0))) -> 67.633333 | I6: =IF(INDEX(学年度总表!$I$3:$I$1025,MATCH($E6,学年度总表!$E$3:$E$1025,0))="","",INDEX(学年度总表!$I$3:$I$1025,MATCH($E6,学年度总表!$E$3:$E$1025,0))) -> 5.5 | J6: =IF(INDEX(学年度总表!$J$3:$J$1025,MATCH($E6,学年度总表!$E$3:$E$1025,0))="","",INDEX(学年度总表!$J$3:$J$1025,MATCH($E6,学年度总表!$E$3:$E$1025,0))) -> 83.93 | K6: =IF(INDEX(学年度总表!$K$3:$K$1025,MATCH($E6,学年度总表!$E$3:$E$1025,0))="","",INDEX(学年度总表!$K$3:$K$1025,MATCH($E6,学年度总表!$E$3:$E$1025,0))) -> 10 | L6: =IF(INDEX(学年度总表!$L$3:$L$1025,MATCH($E6,学年度总表!$E$3:$E$1025,0))="","",INDEX(学年度总表!$L$3:$L$1025,MATCH($E6,学年度总表!$E$3:$E$1025,0))) -> 71.75 | M6: =IF(INDEX(学年度总表!$M$3:$M$1025,MATCH($E6,学年度总表!$E$3:$E$1025,0))="","",INDEX(学年度总表!$M$3:$M$1025,MATCH($E6,学年度总表!$E$3:$E$1025,0))) -> 5.4 | N6: =IF(INDEX(学年度总表!$N$3:$N$1025,MATCH($E6,学年度总表!$E$3:$E$1025,0))="","",INDEX(学年度总表!$N$3:$N$1025,MATCH($E6,学年度总表!$E$3:$E$1025,0))) -> 87.15 | O6: =IF(INDEX(学年度总表!$O$3:$O$1025,MATCH($E6,学年度总表!$E$3:$E$1025,0))="","",INDEX(学年度总表!$O$3:$O$1025,MATCH($E6,学年度总表!$E$3:$E$1025,0))) -> 171.08 | P6: =IF(INDEX(学年度总表!$P$3:$P$1025,MATCH($E6,学年度总表!$E$3:$E$1025,0))="","",INDEX(学年度总表!$P$3:$P$1025,MATCH($E6,学年度总表!$E$3:$E$1025,0))) -> 校一等 | Q6: =IF(INDEX(学年度总表!$Q$3:$Q$1025,MATCH($E6,学年度总表!$E$3:$E$1025,0))="","",INDEX(学年度总表!$Q$3:$Q$1025,MATCH($E6,学年度总表!$E$3:$E$1025,0)))
A7: =IF(INDEX(学年度总表!$A$3:$A$1025,MATCH($E7,学年度总表!$E$3:$E$1025,0))="","",INDEX(学年度总表!$A$3:$A$1025,MATCH($E7,学年度总表!$E$3:$E$1025,0))) -> 20 | B7: =IF(INDEX(学年度总表!$B$3:$B$1025,MATCH($E7,学年度总表!$E$3:$E$1025,0))="","",INDEX(学年度总表!$B$3:$B$1025,MATCH($E7,学年度总表!$E$3:$E$1025,0))) -> 5 | C7: =IF(INDEX(学年度总表!$C$3:$C$1025,MATCH($E7,学年度总表!$E$3:$E$1025,0))="","",INDEX(学年度总表!$C$3:$C$1025,MATCH($E7,学年度总表!$E$3:$E$1025,0))) -> 计科 | D7: =IF(INDEX(学年度总表!$D$3:$D$1025,MATCH($E7,学年度总表!$E$3:$E$1025,0))="","",INDEX(学年度总表!$D$3:$D$1025,MATCH($E7,学年度总表!$E$3:$E$1025,0))) -> 计科三班 | E7: 250450315 | F7: =IF(INDEX(学年度总表!$F$3:$F$1025,MATCH($E7,学年度总表!$E$3:$E$1025,0))="","",INDEX(学年度总表!$F$3:$F$1025,MATCH($E7,学年度总表!$E$3:$E$1025,0))) -> 程俊杰 | G7: =IF(INDEX(学年度总表!$G$3:$G$1025,MATCH($E7,学年度总表!$E$3:$E$1025,0))="","",INDEX(学年度总表!$G$3:$G$1025,MATCH($E7,学年度总表!$E$3:$E$1025,0))) -> 9.8 | H7: =IF(INDEX(学年度总表!$H$3:$H$1025,MATCH($E7,学年度总表!$E$3:$E$1025,0))="","",INDEX(学年度总表!$H$3:$H$1025,MATCH($E7,学年度总表!$E$3:$E$1025,0))) -> 71.232558 | I7: =IF(INDEX(学年度总表!$I$3:$I$1025,MATCH($E7,学年度总表!$E$3:$E$1025,0))="","",INDEX(学年度总表!$I$3:$I$1025,MATCH($E7,学年度总表!$E$3:$E$1025,0))) -> 5.2 | J7: =IF(INDEX(学年度总表!$J$3:$J$1025,MATCH($E7,学年度总表!$E$3:$E$1025,0))="","",INDEX(学年度总表!$J$3:$J$1025,MATCH($E7,学年度总表!$E$3:$E$1025,0))) -> 86.23 | K7: =IF(INDEX(学年度总表!$K$3:$K$1025,MATCH($E7,学年度总表!$E$3:$E$1025,0))="","",INDEX(学年度总表!$K$3:$K$1025,MATCH($E7,学年度总表!$E$3:$E$1025,0))) -> 9 | L7: =IF(INDEX(学年度总表!$L$3:$L$1025,MATCH($E7,学年度总表!$E$3:$E$1025,0))="","",INDEX(学年度总表!$L$3:$L$1025,MATCH($E7,学年度总表!$E$3:$E$1025,0))) -> 68.5 | M7: =IF(INDEX(学年度总表!$M$3:$M$1025,MATCH($E7,学年度总表!$E$3:$E$1025,0))="","",INDEX(学年度总表!$M$3:$M$1025,MATCH($E7,学年度总表!$E$3:$E$1025,0))) -> 5.2 | N7: =IF(INDEX(学年度总表!$N$3:$N$1025,MATCH($E7,学年度总表!$E$3:$E$1025,0))="","",INDEX(学年度总表!$N$3:$N$1025,MATCH($E7,学年度总表!$E$3:$E$1025,0))) -> 82.7 | O7: =IF(INDEX(学年度总表!$O$3:$O$1025,MATCH($E7,学年度总表!$E$3:$E$1025,0))="","",INDEX(学年度总表!$O$3:$O$1025,MATCH($E7,学年度总表!$E$3:$E$1025,0))) -> 168.93 | P7: =IF(INDEX(学年度总表!$P$3:$P$1025,MATCH($E7,学年度总表!$E$3:$E$1025,0))="","",INDEX(学年度总表!$P$3:$P$1025,MATCH($E7,学年度总表!$E$3:$E$1025,0))) -> 校二等 | Q7: =IF(INDEX(学年度总表!$Q$3:$Q$1025,MATCH($E7,学年度总表!$E$3:$E$1025,0))="","",INDEX(学年度总表!$Q$3:$Q$1025,MATCH($E7,学年度总表!$E$3:$E$1025,0)))
A8: =IF(INDEX(学年度总表!$A$3:$A$1025,MATCH($E8,学年度总表!$E$3:$E$1025,0))="","",INDEX(学年度总表!$A$3:$A$1025,MATCH($E8,学年度总表!$E$3:$E$1025,0))) -> 26 | B8: =IF(INDEX(学年度总表!$B$3:$B$1025,MATCH($E8,学年度总表!$E$3:$E$1025,0))="","",INDEX(学年度总表!$B$3:$B$1025,MATCH($E8,学年度总表!$E$3:$E$1025,0))) -> 6 | C8: =IF(INDEX(学年度总表!$C$3:$C$1025,MATCH($E8,学年度总表!$E$3:$E$1025,0))="","",INDEX(学年度总表!$C$3:$C$1025,MATCH($E8,学年度总表!$E$3:$E$1025,0))) -> 计科 | D8: =IF(INDEX(学年度总表!$D$3:$D$1025,MATCH($E8,学年度总表!$E$3:$E$1025,0))="","",INDEX(学年度总表!$D$3:$D$1025,MATCH($E8,学年度总表!$E$3:$E$1025,0))) -> 计科二班 | E8: 250450219 | F8: =IF(INDEX(学年度总表!$F$3:$F$1025,MATCH($E8,学年度总表!$E$3:$E$1025,0))="","",INDEX(学年度总表!$F$3:$F$1025,MATCH($E8,学年度总表!$E$3:$E$1025,0))) -> 郭子萌 | G8: =IF(INDEX(学年度总表!$G$3:$G$1025,MATCH($E8,学年度总表!$E$3:$E$1025,0))="","",INDEX(学年度总表!$G$3:$G$1025,MATCH($E8,学年度总表!$E$3:$E$1025,0))) -> 9.8 | H8: =IF(INDEX(学年度总表!$H$3:$H$1025,MATCH($E8,学年度总表!$E$3:$E$1025,0))="","",INDEX(学年度总表!$H$3:$H$1025,MATCH($E8,学年度总表!$E$3:$E$1025,0))) -> 68.573171 | I8: =IF(INDEX(学年度总表!$I$3:$I$1025,MATCH($E8,学年度总表!$E$3:$E$1025,0))="","",INDEX(学年度总表!$I$3:$I$1025,MATCH($E8,学年度总表!$E$3:$E$1025,0))) -> 4.2 | J8: =IF(INDEX(学年度总表!$J$3:$J$1025,MATCH($E8,学年度总表!$E$3:$E$1025,0))="","",INDEX(学年度总表!$J$3:$J$1025,MATCH($E8,学年度总表!$E$3:$E$1025,0))) -> 82.57 | K8: =IF(INDEX(学年度总表!$K$3:$K$1025,MATCH($E8,学年度总表!$E$3:$E$1025,0))="","",INDEX(学年度总表!$K$3:$K$1025,MATCH($E8,学年度总表!$E$3:$E$1025,0))) -> 9.8 | L8: =IF(INDEX(学年度总表!$L$3:$L$1025,MATCH($E8,学年度总表!$E$3:$E$1025,0))="","",INDEX(学年度总表!$L$3:$L$1025,MATCH($E8,学年度总表!$E$3:$E$1025,0))) -> 71.45 | M8: =IF(INDEX(学年度总表!$M$3:$M$1025,MATCH($E8,学年度总表!$E$3:$E$1025,0))="","",INDEX(学年度总表!$M$3:$M$1025,MATCH($E8,学年度总表!$E$3:$E$1025,0))) -> 4 | N8: =IF(INDEX(学年度总表!$N$3:$N$1025,MATCH($E8,学年度总表!$E$3:$E$1025,0))="","",INDEX(学年度总表!$N$3:$N$1025,MATCH($E8,学年度总表!$E$3:$E$1025,0))) -> 85.25 | O8: =IF(INDEX(学年度总表!$O$3:$O$1025,MATCH($E8,学年度总表!$E$3:$E$1025,0))="","",INDEX(学年度总表!$O$3:$O$1025,MATCH($E8,学年度总表!$E$3:$E$1025,0))) -> 167.82 | P8: =IF(INDEX(学年度总表!$P$3:$P$1025,MATCH($E8,学年度总表!$E$3:$E$1025,0))="","",INDEX(学年度总表!$P$3:$P$1025,MATCH($E8,学年度总表!$E$3:$E$1025,0))) -> 校二等 | Q8: =IF(INDEX(学年度总表!$Q$3:$Q$1025,MATCH($E8,学年度总表!$E$3:$E$1025,0))="","",INDEX(学年度总表!$Q$3:$Q$1025,MATCH($E8,学年度总表!$E$3:$E$1025,0)))
A9: =IF(INDEX(学年度总表!$A$3:$A$1025,MATCH($E9,学年度总表!$E$3:$E$1025,0))="","",INDEX(学年度总表!$A$3:$A$1025,MATCH($E9,学年度总表!$E$3:$E$1025,0))) -> 30 | B9: =IF(INDEX(学年度总表!$B$3:$B$1025,MATCH($E9,学年度总表!$E$3:$E$1025,0))="","",INDEX(学年度总表!$B$3:$B$1025,MATCH($E9,学年度总表!$E$3:$E$1025,0))) -> 7 | C9: =IF(INDEX(学年度总表!$C$3:$C$1025,MATCH($E9,学年度总表!$E$3:$E$1025,0))="","",INDEX(学年度总表!$C$3:$C$1025,MATCH($E9,学年度总表!$E$3:$E$1025,0))) -> 计科 | D9: =IF(INDEX(学年度总表!$D$3:$D$1025,MATCH($E9,学年度总表!$E$3:$E$1025,0))="","",INDEX(学年度总表!$D$3:$D$1025,MATCH($E9,学年度总表!$E$3:$E$1025,0))) -> 计科三班 | E9: 250450312 | F9: =IF(INDEX(学年度总表!$F$3:$F$1025,MATCH($E9,学年度总表!$E$3:$E$1025,0))="","",INDEX(学年度总表!$F$3:$F$1025,MATCH($E9,学年度总表!$E$3:$E$1025,0))) -> 赵紫仪 | G9: =IF(INDEX(学年度总表!$G$3:$G$1025,MATCH($E9,学年度总表!$E$3:$E$1025,0))="","",INDEX(学年度总表!$G$3:$G$1025,MATCH($E9,学年度总表!$E$3:$E$1025,0))) -> 13.1 | H9: =IF(INDEX(学年度总表!$H$3:$H$1025,MATCH($E9,学年度总表!$E$3:$E$1025,0))="","",INDEX(学年度总表!$H$3:$H$1025,MATCH($E9,学年度总表!$E$3:$E$1025,0))) -> 70.646341 | I9: =IF(INDEX(学年度总表!$I$3:$I$1025,MATCH($E9,学年度总表!$E$3:$E$1025,0))="","",INDEX(学年度总表!$I$3:$I$1025,MATCH($E9,学年度总表!$E$3:$E$1025,0))) -> 4.5 | J9: =IF(INDEX(学年度总表!$J$3:$J$1025,MATCH($E9,学年度总表!$E$3:$E$1025,0))="","",INDEX(学年度总表!$J$3:$J$1025,MATCH($E9,学年度总表!$E$3:$E$1025,0))) -> 88.25 | K9: =IF(INDEX(学年度总表!$K$3:$K$1025,MATCH($E9,学年度总表!$E$3:$E$1025,0))="","",INDEX(学年度总表!$K$3:$K$1025,MATCH($E9,学年度总表!$E$3:$E$1025,0))) -> 11 | L9: =IF(INDEX(学年度总表!$L$3:$L$1025,MATCH($E9,学年度总表!$E$3:$E$1025,0))="","",INDEX(学年度总表!$L$3:$L$1025,MATCH($E9,学年度总表!$E$3:$E$1025,0))) -> 61.75 | M9: =IF(INDEX(学年度总表!$M$3:$M$1025,MATCH($E9,学年度总表!$E$3:$E$1025,0))="","",INDEX(学年度总表!$M$3:$M$1025,MATCH($E9,学年度总表!$E$3:$E$1025,0))) -> 5.4 | N9: =IF(INDEX(学年度总表!$N$3:$N$1025,MATCH($E9,学年度总表!$E$3:$E$1025,0))="","",INDEX(学年度总表!$N$3:$N$1025,MATCH($E9,学年度总表!$E$3:$E$1025,0))) -> 78.15 | O9: =IF(INDEX(学年度总表!$O$3:$O$1025,MATCH($E9,学年度总表!$E$3:$E$1025,0))="","",INDEX(学年度总表!$O$3:$O$1025,MATCH($E9,学年度总表!$E$3:$E$1025,0))) -> 166.4 | P9: =IF(INDEX(学年度总表!$P$3:$P$1025,MATCH($E9,学年度总表!$E$3:$E$1025,0))="","",INDEX(学年度总表!$P$3:$P$1025,MATCH($E9,学年度总表!$E$3:$E$1025,0))) -> 校二等 | Q9: =IF(INDEX(学年度总表!$Q$3:$Q$1025,MATCH($E9,学年度总表!$E$3:$E$1025,0))="","",INDEX(学年度总表!$Q$3:$Q$1025,MATCH($E9,学年度总表!$E$3:$E$1025,0)))
A10: =IF(INDEX(学年度总表!$A$3:$A$1025,MATCH($E10,学年度总表!$E$3:$E$1025,0))="","",INDEX(学年度总表!$A$3:$A$1025,MATCH($E10,学年度总表!$E$3:$E$1025,0))) -> 32 | B10: =IF(INDEX(学年度总表!$B$3:$B$1025,MATCH($E10,学年度总表!$E$3:$E$1025,0))="","",INDEX(学年度总表!$B$3:$B$1025,MATCH($E10,学年度总表!$E$3:$E$1025,0))) -> 8 | C10: =IF(INDEX(学年度总表!$C$3:$C$1025,MATCH($E10,学年度总表!$E$3:$E$1025,0))="","",INDEX(学年度总表!$C$3:$C$1025,MATCH($E10,学年度总表!$E$3:$E$1025,0))) -> 计科 | D10: =IF(INDEX(学年度总表!$D$3:$D$1025,MATCH($E10,学年度总表!$E$3:$E$1025,0))="","",INDEX(学年度总表!$D$3:$D$1025,MATCH($E10,学年度总表!$E$3:$E$1025,0))) -> 计科一班 | E10: 250450122 | F10: =IF(INDEX(学年度总表!$F$3:$F$1025,MATCH($E10,学年度总表!$E$3:$E$1025,0))="","",INDEX(学年度总表!$F$3:$F$1025,MATCH($E10,学年度总表!$E$3:$E$1025,0))) -> 张淅傲 | G10: =IF(INDEX(学年度总表!$G$3:$G$1025,MATCH($E10,学年度总表!$E$3:$E$1025,0))="","",INDEX(学年度总表!$G$3:$G$1025,MATCH($E10,学年度总表!$E$3:$E$1025,0))) -> 12.8 | H10: =IF(INDEX(学年度总表!$H$3:$H$1025,MATCH($E10,学年度总表!$E$3:$E$1025,0))="","",INDEX(学年度总表!$H$3:$H$1025,MATCH($E10,学年度总表!$E$3:$E$1025,0))) -> 66.533333 | I10: =IF(INDEX(学年度总表!$I$3:$I$1025,MATCH($E10,学年度总表!$E$3:$E$1025,0))="","",INDEX(学年度总表!$I$3:$I$1025,MATCH($E10,学年度总表!$E$3:$E$1025,0))) -> 5.8 | J10: =IF(INDEX(学年度总表!$J$3:$J$1025,MATCH($E10,学年度总表!$E$3:$E$1025,0))="","",INDEX(学年度总表!$J$3:$J$1025,MATCH($E10,学年度总表!$E$3:$E$1025,0))) -> 85.13 | K10: =IF(INDEX(学年度总表!$K$3:$K$1025,MATCH($E10,学年度总表!$E$3:$E$1025,0))="","",INDEX(学年度总表!$K$3:$K$1025,MATCH($E10,学年度总表!$E$3:$E$1025,0))) -> 11.3 | L10: =IF(INDEX(学年度总表!$L$3:$L$1025,MATCH($E10,学年度总表!$E$3:$E$1025,0))="","",INDEX(学年度总表!$L$3:$L$1025,MATCH($E10,学年度总表!$E$3:$E$1025,0))) -> 61.55 | M10: =IF(INDEX(学年度总表!$M$3:$M$1025,MATCH($E10,学年度总表!$E$3:$E$1025,0))="","",INDEX(学年度总表!$M$3:$M$1025,MATCH($E10,学年度总表!$E$3:$E$1025,0))) -> 8.4 | N10: =IF(INDEX(学年度总表!$N$3:$N$1025,MATCH($E10,学年度总表!$E$3:$E$1025,0))="","",INDEX(学年度总表!$N$3:$N$1025,MATCH($E10,学年度总表!$E$3:$E$1025,0))) -> 81.25 | O10: =IF(INDEX(学年度总表!$O$3:$O$1025,MATCH($E10,学年度总表!$E$3:$E$1025,0))="","",INDEX(学年度总表!$O$3:$O$1025,MATCH($E10,学年度总表!$E$3:$E$1025,0))) -> 166.38 | P10: =IF(INDEX(学年度总表!$P$3:$P$1025,MATCH($E10,学年度总表!$E$3:$E$1025,0))="","",INDEX(学年度总表!$P$3:$P$1025,MATCH($E10,学年度总表!$E$3:$E$1025,0))) | Q10: =IF(INDEX(学年度总表!$Q$3:$Q$1025,MATCH($E10,学年度总表!$E$3:$E$1025,0))="","",INDEX(学年度总表!$Q$3:$Q$1025,MATCH($E10,学年度总表!$E$3:$E$1025,0)))
A11: =IF(INDEX(学年度总表!$A$3:$A$1025,MATCH($E11,学年度总表!$E$3:$E$1025,0))="","",INDEX(学年度总表!$A$3:$A$1025,MATCH($E11,学年度总表!$E$3:$E$1025,0))) -> 41 | B11: =IF(INDEX(学年度总表!$B$3:$B$1025,MATCH($E11,学年度总表!$E$3:$E$1025,0))="","",INDEX(学年度总表!$B$3:$B$1025,MATCH($E11,学年度总表!$E$3:$E$1025,0))) -> 9 | C11: =IF(INDEX(学年度总表!$C$3:$C$1025,MATCH($E11,学年度总表!$E$3:$E$1025,0))="","",INDEX(学年度总表!$C$3:$C$1025,MATCH($E11,学年度总表!$E$3:$E$1025,0))) -> 计科 | D11: =IF(INDEX(学年度总表!$D$3:$D$1025,MATCH($E11,学年度总表!$E$3:$E$1025,0))="","",INDEX(学年度总表!$D$3:$D$1025,MATCH($E11,学年度总表!$E$3:$E$1025,0))) -> 计科一班 | E11: 250450124 | F11: =IF(INDEX(学年度总表!$F$3:$F$1025,MATCH($E11,学年度总表!$E$3:$E$1025,0))="","",INDEX(学年度总表!$F$3:$F$1025,MATCH($E11,学年度总表!$E$3:$E$1025,0))) -> 刘奕含 | G11: =IF(INDEX(学年度总表!$G$3:$G$1025,MATCH($E11,学年度总表!$E$3:$E$1025,0))="","",INDEX(学年度总表!$G$3:$G$1025,MATCH($E11,学年度总表!$E$3:$E$1025,0))) -> 10.8 | H11: =IF(INDEX(学年度总表!$H$3:$H$1025,MATCH($E11,学年度总表!$E$3:$E$1025,0))="","",INDEX(学年度总表!$H$3:$H$1025,MATCH($E11,学年度总表!$E$3:$E$1025,0))) -> 65.865854 | I11: =IF(INDEX(学年度总表!$I$3:$I$1025,MATCH($E11,学年度总表!$E$3:$E$1025,0))="","",INDEX(学年度总表!$I$3:$I$1025,MATCH($E11,学年度总表!$E$3:$E$1025,0))) -> 5 | J11: =IF(INDEX(学年度总表!$J$3:$J$1025,MATCH($E11,学年度总表!$E$3:$E$1025,0))="","",INDEX(学年度总表!$J$3:$J$1025,MATCH($E11,学年度总表!$E$3:$E$1025,0))) -> 81.67 | K11: =IF(INDEX(学年度总表!$K$3:$K$1025,MATCH($E11,学年度总表!$E$3:$E$1025,0))="","",INDEX(学年度总表!$K$3:$K$1025,MATCH($E11,学年度总表!$E$3:$E$1025,0))) -> 10.8 | L11: =IF(INDEX(学年度总表!$L$3:$L$1025,MATCH($E11,学年度总表!$E$3:$E$1025,0))="","",INDEX(学年度总表!$L$3:$L$1025,MATCH($E11,学年度总表!$E$3:$E$1025,0))) -> 66.24 | M11: =IF(INDEX(学年度总表!$M$3:$M$1025,MATCH($E11,学年度总表!$E$3:$E$1025,0))="","",INDEX(学年度总表!$M$3:$M$1025,MATCH($E11,学年度总表!$E$3:$E$1025,0))) -> 6.2 | N11: =IF(INDEX(学年度总表!$N$3:$N$1025,MATCH($E11,学年度总表!$E$3:$E$1025,0))="","",INDEX(学年度总表!$N$3:$N$1025,MATCH($E11,学年度总表!$E$3:$E$1025,0))) -> 83.24 | O11: =IF(INDEX(学年度总表!$O$3:$O$1025,MATCH($E11,学年度总表!$E$3:$E$1025,0))="","",INDEX(学年度总表!$O$3:$O$1025,MATCH($E11,学年度总表!$E$3:$E$1025,0))) -> 164.91 | P11: =IF(INDEX(学年度总表!$P$3:$P$1025,MATCH($E11,学年度总表!$E$3:$E$1025,0))="","",INDEX(学年度总表!$P$3:$P$1025,MATCH($E11,学年度总表!$E$3:$E$1025,0))) -> 校二等 | Q11: =IF(INDEX(学年度总表!$Q$3:$Q$1025,MATCH($E11,学年度总表!$E$3:$E$1025,0))="","",INDEX(学年度总表!$Q$3:$Q$1025,MATCH($E11,学年度总表!$E$3:$E$1025,0)))
A12: =IF(INDEX(学年度总表!$A$3:$A$1025,MATCH($E12,学年度总表!$E$3:$E$1025,0))="","",INDEX(学年度总表!$A$3:$A$1025,MATCH($E12,学年度总表!$E$3:$E$1025,0))) -> 42 | B12: =IF(INDEX(学年度总表!$B$3:$B$1025,MATCH($E12,学年度总表!$E$3:$E$1025,0))="","",INDEX(学年度总表!$B$3:$B$1025,MATCH($E12,学年度总表!$E$3:$E$1025,0))) -> 10 | C12: =IF(INDEX(学年度总表!$C$3:$C$1025,MATCH($E12,学年度总表!$E$3:$E$1025,0))="","",INDEX(学年度总表!$C$3:$C$1025,MATCH($E12,学年度总表!$E$3:$E$1025,0))) -> 计科 | D12: =IF(INDEX(学年度总表!$D$3:$D$1025,MATCH($E12,学年度总表!$E$3:$E$1025,0))="","",INDEX(学年度总表!$D$3:$D$1025,MATCH($E12,学年度总表!$E$3:$E$1025,0))) -> 计科三班 | E12: 250450323 | F12: =IF(INDEX(学年度总表!$F$3:$F$1025,MATCH($E12,学年度总表!$E$3:$E$1025,0))="","",INDEX(学年度总表!$F$3:$F$1025,MATCH($E12,学年度总表!$E$3:$E$1025,0))) -> 吕佳妮 | G12: =IF(INDEX(学年度总表!$G$3:$G$1025,MATCH($E12,学年度总表!$E$3:$E$1025,0))="","",INDEX(学年度总表!$G$3:$G$1025,MATCH($E12,学年度总表!$E$3:$E$1025,0))) -> 10.8 | H12: =IF(INDEX(学年度总表!$H$3:$H$1025,MATCH($E12,学年度总表!$E$3:$E$1025,0))="","",INDEX(学年度总表!$H$3:$H$1025,MATCH($E12,学年度总表!$E$3:$E$1025,0))) -> 69.170732 | I12: =IF(INDEX(学年度总表!$I$3:$I$1025,MATCH($E12,学年度总表!$E$3:$E$1025,0))="","",INDEX(学年度总表!$I$3:$I$1025,MATCH($E12,学年度总表!$E$3:$E$1025,0))) -> 4.5 | J12: =IF(INDEX(学年度总表!$J$3:$J$1025,MATCH($E12,学年度总表!$E$3:$E$1025,0))="","",INDEX(学年度总表!$J$3:$J$1025,MATCH($E12,学年度总表!$E$3:$E$1025,0))) -> 84.47 | K12: =IF(INDEX(学年度总表!$K$3:$K$1025,MATCH($E12,学年度总表!$E$3:$E$1025,0))="","",INDEX(学年度总表!$K$3:$K$1025,MATCH($E12,学年度总表!$E$3:$E$1025,0))) -> 9 | L12: =IF(INDEX(学年度总表!$L$3:$L$1025,MATCH($E12,学年度总表!$E$3:$E$1025,0))="","",INDEX(学年度总表!$L$3:$L$1025,MATCH($E12,学年度总表!$E$3:$E$1025,0))) -> 65.49 | M12: =IF(INDEX(学年度总表!$M$3:$M$1025,MATCH($E12,学年度总表!$E$3:$E$1025,0))="","",INDEX(学年度总表!$M$3:$M$1025,MATCH($E12,学年度总表!$E$3:$E$1025,0))) -> 5.9 | N12: =IF(INDEX(学年度总表!$N$3:$N$1025,MATCH($E12,学年度总表!$E$3:$E$1025,0))="","",INDEX(学年度总表!$N$3:$N$1025,MATCH($E12,学年度总表!$E$3:$E$1025,0))) -> 80.39 | O12: =IF(INDEX(学年度总表!$O$3:$O$1025,MATCH($E12,学年度总表!$E$3:$E$1025,0))="","",INDEX(学年度总表!$O$3:$O$1025,MATCH($E12,学年度总表!$E$3:$E$1025,0))) -> 164.86 | P12: =IF(INDEX(学年度总表!$P$3:$P$1025,MATCH($E12,学年度总表!$E$3:$E$1025,0))="","",INDEX(学年度总表!$P$3:$P$1025,MATCH($E12,学年度总表!$E$3:$E$1025,0))) -> 校三等 | Q12: =IF(INDEX(学年度总表!$Q$3:$Q$1025,MATCH($E12,学年度总表!$E$3:$E$1025,0))="","",INDEX(学年度总表!$Q$3:$Q$1025,MATCH($E12,学年度总表!$E$3:$E$1025,0)))
A13: =IF(INDEX(学年度总表!$A$3:$A$1025,MATCH($E13,学年度总表!$E$3:$E$1025,0))="","",INDEX(学年度总表!$A$3:$A$1025,MATCH($E13,学年度总表!$E$3:$E$1025,0))) -> 45 | B13: =IF(INDEX(学年度总表!$B$3:$B$1025,MATCH($E13,学年度总表!$E$3:$E$1025,0))="","",INDEX(学年度总表!$B$3:$B$1025,MATCH($E13,学年度总表!$E$3:$E$1025,0))) -> 11 | C13: =IF(INDEX(学年度总表!$C$3:$C$1025,MATCH($E13,学年度总表!$E$3:$E$1025,0))="","",INDEX(学年度总表!$C$3:$C$1025,MATCH($E13,学年度总表!$E$3:$E$1025,0))) -> 计科 | D13: =IF(INDEX(学年度总表!$D$3:$D$1025,MATCH($E13,学年度总表!$E$3:$E$1025,0))="","",INDEX(学年度总表!$D$3:$D$1025,MATCH($E13,学年度总表!$E$3:$E$1025,0))) -> 计科二班 | E13: 250450232 | F13: =IF(INDEX(学年度总表!$F$3:$F$1025,MATCH($E13,学年度总表!$E$3:$E$1025,0))="","",INDEX(学年度总表!$F$3:$F$1025,MATCH($E13,学年度总表!$E$3:$E$1025,0))) -> 聂煜翀 | G13: =IF(INDEX(学年度总表!$G$3:$G$1025,MATCH($E13,学年度总表!$E$3:$E$1025,0))="","",INDEX(学年度总表!$G$3:$G$1025,MATCH($E13,学年度总表!$E$3:$E$1025,0))) -> 10.3 | H13: =IF(INDEX(学年度总表!$H$3:$H$1025,MATCH($E13,学年度总表!$E$3:$E$1025,0))="","",INDEX(学年度总表!$H$3:$H$1025,MATCH($E13,学年度总表!$E$3:$E$1025,0))) -> 67.366667 | I13: =IF(INDEX(学年度总表!$I$3:$I$1025,MATCH($E13,学年度总表!$E$3:$E$1025,0))="","",INDEX(学年度总表!$I$3:$I$1025,MATCH($E13,学年度总表!$E$3:$E$1025,0))) -> 4.9 | J13: =IF(INDEX(学年度总表!$J$3:$J$1025,MATCH($E13,学年度总表!$E$3:$E$1025,0))="","",INDEX(学年度总表!$J$3:$J$1025,MATCH($E13,学年度总表!$E$3:$E$1025,0))) -> 82.57 | K13: =IF(INDEX(学年度总表!$K$3:$K$1025,MATCH($E13,学年度总表!$E$3:$E$1025,0))="","",INDEX(学年度总表!$K$3:$K$1025,MATCH($E13,学年度总表!$E$3:$E$1025,0))) -> 9.8 | L13: =IF(INDEX(学年度总表!$L$3:$L$1025,MATCH($E13,学年度总表!$E$3:$E$1025,0))="","",INDEX(学年度总表!$L$3:$L$1025,MATCH($E13,学年度总表!$E$3:$E$1025,0))) -> 67.57 | M13: =IF(INDEX(学年度总表!$M$3:$M$1025,MATCH($E13,学年度总表!$E$3:$E$1025,0))="","",INDEX(学年度总表!$M$3:$M$1025,MATCH($E13,学年度总表!$E$3:$E$1025,0))) -> 4.7 | N13: =IF(INDEX(学年度总表!$N$3:$N$1025,MATCH($E13,学年度总表!$E$3:$E$1025,0))="","",INDEX(学年度总表!$N$3:$N$1025,MATCH($E13,学年度总表!$E$3:$E$1025,0))) -> 82.07 | O13: =IF(INDEX(学年度总表!$O$3:$O$1025,MATCH($E13,学年度总表!$E$3:$E$1025,0))="","",INDEX(学年度总表!$O$3:$O$1025,MATCH($E13,学年度总表!$E$3:$E$1025,0))) -> 164.64 | P13: =IF(INDEX(学年度总表!$P$3:$P$1025,MATCH($E13,学年度总表!$E$3:$E$1025,0))="","",INDEX(学年度总表!$P$3:$P$1025,MATCH($E13,学年度总表!$E$3:$E$1025,0))) -> 校三等 | Q13: =IF(INDEX(学年度总表!$Q$3:$Q$1025,MATCH($E13,学年度总表!$E$3:$E$1025,0))="","",INDEX(学年度总表!$Q$3:$Q$1025,MATCH($E13,学年度总表!$E$3:$E$1025,0)))
A14: =IF(INDEX(学年度总表!$A$3:$A$1025,MATCH($E14,学年度总表!$E$3:$E$1025,0))="","",INDEX(学年度总表!$A$3:$A$1025,MATCH($E14,学年度总表!$E$3:$E$1025,0))) -> 46 | B14: =IF(INDEX(学年度总表!$B$3:$B$1025,MATCH($E14,学年度总表!$E$3:$E$1025,0))="","",INDEX(学年度总表!$B$3:$B$1025,MATCH($E14,学年度总表!$E$3:$E$1025,0))) -> 12 | C14: =IF(INDEX(学年度总表!$C$3:$C$1025,MATCH($E14,学年度总表!$E$3:$E$1025,0))="","",INDEX(学年度总表!$C$3:$C$1025,MATCH($E14,学年度总表!$E$3:$E$1025,0))) -> 计科 | D14: =IF(INDEX(学年度总表!$D$3:$D$1025,MATCH($E14,学年度总表!$E$3:$E$1025,0))="","",INDEX(学年度总表!$D$3:$D$1025,MATCH($E14,学年度总表!$E$3:$E$1025,0))) -> 计科三班 | E14: 250450322 | F14: =IF(INDEX(学年度总表!$F$3:$F$1025,MATCH($E14,学年度总表!$E$3:$E$1025,0))="","",INDEX(学年度总表!$F$3:$F$1025,MATCH($E14,学年度总表!$E$3:$E$1025,0))) -> 袁世博 | G14: =IF(INDEX(学年度总表!$G$3:$G$1025,MATCH($E14,学年度总表!$E$3:$E$1025,0))="","",INDEX(学年度总表!$G$3:$G$1025,MATCH($E14,学年度总表!$E$3:$E$1025,0))) -> 11.3 | H14: =IF(INDEX(学年度总表!$H$3:$H$1025,MATCH($E14,学年度总表!$E$3:$E$1025,0))="","",INDEX(学年度总表!$H$3:$H$1025,MATCH($E14,学年度总表!$E$3:$E$1025,0))) -> 68.1 | I14: =IF(INDEX(学年度总表!$I$3:$I$1025,MATCH($E14,学年度总表!$E$3:$E$1025,0))="","",INDEX(学年度总表!$I$3:$I$1025,MATCH($E14,学年度总表!$E$3:$E$1025,0))) -> 3.5 | J14: =IF(INDEX(学年度总表!$J$3:$J$1025,MATCH($E14,学年度总表!$E$3:$E$1025,0))="","",INDEX(学年度总表!$J$3:$J$1025,MATCH($E14,学年度总表!$E$3:$E$1025,0))) -> 82.9 | K14: =IF(INDEX(学年度总表!$K$3:$K$1025,MATCH($E14,学年度总表!$E$3:$E$1025,0))="","",INDEX(学年度总表!$K$3:$K$1025,MATCH($E14,学年度总表!$E$3:$E$1025,0))) -> 9 | L14: =IF(INDEX(学年度总表!$L$3:$L$1025,MATCH($E14,学年度总表!$E$3:$E$1025,0))="","",INDEX(学年度总表!$L$3:$L$1025,MATCH($E14,学年度总表!$E$3:$E$1025,0))) -> 66.51 | M14: =IF(INDEX(学年度总表!$M$3:$M$1025,MATCH($E14,学年度总表!$E$3:$E$1025,0))="","",INDEX(学年度总表!$M$3:$M$1025,MATCH($E14,学年度总表!$E$3:$E$1025,0))) -> 6.2 | N14: =IF(INDEX(学年度总表!$N$3:$N$1025,MATCH($E14,学年度总表!$E$3:$E$1025,0))="","",INDEX(学年度总表!$N$3:$N$1025,MATCH($E14,学年度总表!$E$3:$E$1025,0))) -> 81.71 | O14: =IF(INDEX(学年度总表!$O$3:$O$1025,MATCH($E14,学年度总表!$E$3:$E$1025,0))="","",INDEX(学年度总表!$O$3:$O$1025,MATCH($E14,学年度总表!$E$3:$E$1025,0))) -> 164.61 | P14: =IF(INDEX(学年度总表!$P$3:$P$1025,MATCH($E14,学年度总表!$E$3:$E$1025,0))="","",INDEX(学年度总表!$P$3:$P$1025,MATCH($E14,学年度总表!$E$3:$E$1025,0))) -> 校三等 | Q14: =IF(INDEX(学年度总表!$Q$3:$Q$1025,MATCH($E14,学年度总表!$E$3:$E$1025,0))="","",INDEX(学年度总表!$Q$3:$Q$1025,MATCH($E14,学年度总表!$E$3:$E$1025,0)))
... A142: =IF(INDEX(学年度总表!$A$3:$A$1025,MATCH($E142,学年度总表!$E$3:$E$1025,0))="","",INDEX(学年度总表!$A$3:$A$1025,MATCH($E142,学年度总表!$E$3:$E$1025,0))) -> 992 | B142: =IF(INDEX(学年度总表!$B$3:$B$1025,MATCH($E142,学年度总表!$E$3:$E$1025,0))="","",INDEX(学年度总表!$B$3:$B$1025,MATCH($E142,学年度总表!$E$3:$E$1025,0))) -> 140 | C142: =IF(INDEX(学年度总表!$C$3:$C$1025,MATCH($E142,学年度总表!$E$3:$E$1025,0))="","",INDEX(学年度总表!$C$3:$C$1025,MATCH($E142,学年度总表!$E$3:$E$1025,0))) -> 计科 | D142: =IF(INDEX(学年度总表!$D$3:$D$1025,MATCH($E142,学年度总表!$E$3:$E$1025,0))="","",INDEX(学年度总表!$D$3:$D$1025,MATCH($E142,学年度总表!$E$3:$E$1025,0))) -> 计科二班 | E142: 240450320 | F142: =IF(INDEX(学年度总表!$F$3:$F$1025,MATCH($E142,学年度总表!$E$3:$E$1025,0))="","",INDEX(学年度总表!$F$3:$F$1025,MATCH($E142,学年度总表!$E$3:$E$1025,0))) -> 代雨航 | G142: =IF(INDEX(学年度总表!$G$3:$G$1025,MATCH($E142,学年度总表!$E$3:$E$1025,0))="","",INDEX(学年度总表!$G$3:$G$1025,MATCH($E142,学年度总表!$E$3:$E$1025,0))) | H142: =IF(INDEX(学年度总表!$H$3:$H$1025,MATCH($E142,学年度总表!$E$3:$E$1025,0))="","",INDEX(学年度总表!$H$3:$H$1025,MATCH($E142,学年度总表!$E$3:$E$1025,0))) | I142: =IF(INDEX(学年度总表!$I$3:$I$1025,MATCH($E142,学年度总表!$E$3:$E$1025,0))="","",INDEX(学年度总表!$I$3:$I$1025,MATCH($E142,学年度总表!$E$3:$E$1025,0))) | J142: =IF(INDEX(学年度总表!$J$3:$J$1025,MATCH($E142,学年度总表!$E$3:$E$1025,0))="","",INDEX(学年度总表!$J$3:$J$1025,MATCH($E142,学年度总表!$E$3:$E$1025,0))) | K142: =IF(INDEX(学年度总表!$K$3:$K$1025,MATCH($E142,学年度总表!$E$3:$E$1025,0))="","",INDEX(学年度总表!$K$3:$K$1025,MATCH($E142,学年度总表!$E$3:$E$1025,0))) -> 9.8 | L142: =IF(INDEX(学年度总表!$L$3:$L$1025,MATCH($E142,学年度总表!$E$3:$E$1025,0))="","",INDEX(学年度总表!$L$3:$L$1025,MATCH($E142,学年度总表!$E$3:$E$1025,0))) -> 0 | M142: =IF(INDEX(学年度总表!$M$3:$M$1025,MATCH($E142,学年度总表!$E$3:$E$1025,0))="","",INDEX(学年度总表!$M$3:$M$1025,MATCH($E142,学年度总表!$E$3:$E$1025,0))) -> 3 | N142: =IF(INDEX(学年度总表!$N$3:$N$1025,MATCH($E142,学年度总表!$E$3:$E$1025,0))="","",INDEX(学年度总表!$N$3:$N$1025,MATCH($E142,学年度总表!$E$3:$E$1025,0))) -> 12.8 | O142: =IF(INDEX(学年度总表!$O$3:$O$1025,MATCH($E142,学年度总表!$E$3:$E$1025,0))="","",INDEX(学年度总表!$O$3:$O$1025,MATCH($E142,学年度总表!$E$3:$E$1025,0))) -> 12.8 | P142: =IF(INDEX(学年度总表!$P$3:$P$1025,MATCH($E142,学年度总表!$E$3:$E$1025,0))="","",INDEX(学年度总表!$P$3:$P$1025,MATCH($E142,学年度总表!$E$3:$E$1025,0))) | Q142: =IF(INDEX(学年度总表!$Q$3:$Q$1025,MATCH($E142,学年度总表!$E$3:$E$1025,0))="","",INDEX(学年度总表!$Q$3:$Q$1025,MATCH($E142,学年度总表!$E$3:$E$1025,0))) -> 无大一上综测成绩

Sheet 软工排名
A1: 年级排名 | B1: 专业排名 | C1: 专业 | D1: 班级 | E1: 学号 | F1: 姓名 | G1: 大一上 | K1: 大一下 | O1: 学年总分 | P1: 奖学金 | Q1: 备注
G2: 品德总分 | H2: 学业总分 | I2: 文体总分 | J2: 综测总分 | K2: 品德总分 | L2: 学业总分 | M2: 文体总分 | N2: 综测总分
A3: =IF(INDEX(学年度总表!$A$3:$A$1025,MATCH($E3,学年度总表!$E$3:$E$1025,0))="","",INDEX(学年度总表!$A$3:$A$1025,MATCH($E3,学年度总表!$E$3:$E$1025,0))) -> 2 | B3: =IF(INDEX(学年度总表!$B$3:$B$1025,MATCH($E3,学年度总表!$E$3:$E$1025,0))="","",INDEX(学年度总表!$B$3:$B$1025,MATCH($E3,学年度总表!$E$3:$E$1025,0))) -> 1 | C3: =IF(INDEX(学年度总表!$C$3:$C$1025,MATCH($E3,学年度总表!$E$3:$E$1025,0))="","",INDEX(学年度总表!$C$3:$C$1025,MATCH($E3,学年度总表!$E$3:$E$1025,0))) -> 软工 | D3: =IF(INDEX(学年度总表!$D$3:$D$1025,MATCH($E3,学年度总表!$E$3:$E$1025,0))="","",INDEX(学年度总表!$D$3:$D$1025,MATCH($E3,学年度总表!$E$3:$E$1025,0))) -> 软工14班 | E3: 250451433 | F3: =IF(INDEX(学年度总表!$F$3:$F$1025,MATCH($E3,学年度总表!$E$3:$E$1025,0))="","",INDEX(学年度总表!$F$3:$F$1025,MATCH($E3,学年度总表!$E$3:$E$1025,0))) -> 王奕茗 | G3: =IF(INDEX(学年度总表!$G$3:$G$1025,MATCH($E3,学年度总表!$E$3:$E$1025,0))="","",INDEX(学年度总表!$G$3:$G$1025,MATCH($E3,学年度总表!$E$3:$E$1025,0))) -> 9.8 | H3: =IF(INDEX(学年度总表!$H$3:$H$1025,MATCH($E3,学年度总表!$E$3:$E$1025,0))="","",INDEX(学年度总表!$H$3:$H$1025,MATCH($E3,学年度总表!$E$3:$E$1025,0))) -> 72.02 | I3: =IF(INDEX(学年度总表!$I$3:$I$1025,MATCH($E3,学年度总表!$E$3:$E$1025,0))="","",INDEX(学年度总表!$I$3:$I$1025,MATCH($E3,学年度总表!$E$3:$E$1025,0))) -> 5.1 | J3: =IF(INDEX(学年度总表!$J$3:$J$1025,MATCH($E3,学年度总表!$E$3:$E$1025,0))="","",INDEX(学年度总表!$J$3:$J$1025,MATCH($E3,学年度总表!$E$3:$E$1025,0))) -> 86.92 | K3: =IF(INDEX(学年度总表!$K$3:$K$1025,MATCH($E3,学年度总表!$E$3:$E$1025,0))="","",INDEX(学年度总表!$K$3:$K$1025,MATCH($E3,学年度总表!$E$3:$E$1025,0))) -> 11.3 | L3: =IF(INDEX(学年度总表!$L$3:$L$1025,MATCH($E3,学年度总表!$E$3:$E$1025,0))="","",INDEX(学年度总表!$L$3:$L$1025,MATCH($E3,学年度总表!$E$3:$E$1025,0))) -> 73.5 | M3: =IF(INDEX(学年度总表!$M$3:$M$1025,MATCH($E3,学年度总表!$E$3:$E$1025,0))="","",INDEX(学年度总表!$M$3:$M$1025,MATCH($E3,学年度总表!$E$3:$E$1025,0))) -> 8.05 | N3: =IF(INDEX(学年度总表!$N$3:$N$1025,MATCH($E3,学年度总表!$E$3:$E$1025,0))="","",INDEX(学年度总表!$N$3:$N$1025,MATCH($E3,学年度总表!$E$3:$E$1025,0))) -> 92.85 | O3: =IF(INDEX(学年度总表!$O$3:$O$1025,MATCH($E3,学年度总表!$E$3:$E$1025,0))="","",INDEX(学年度总表!$O$3:$O$1025,MATCH($E3,学年度总表!$E$3:$E$1025,0))) -> 179.77 | P3: =IF(INDEX(学年度总表!$P$3:$P$1025,MATCH($E3,学年度总表!$E$3:$E$1025,0))="","",INDEX(学年度总表!$P$3:$P$1025,MATCH($E3,学年度总表!$E$3:$E$1025,0))) -> 国奖 | Q3: =IF(INDEX(学年度总表!$Q$3:$Q$1025,MATCH($E3,学年度总表!$E$3:$E$1025,0))="","",INDEX(学年度总表!$Q$3:$Q$1025,MATCH($E3,学年度总表!$E$3:$E$1025,0)))
A4: =IF(INDEX(学年度总表!$A$3:$A$1025,MATCH($E4,学年度总表!$E$3:$E$1025,0))="","",INDEX(学年度总表!$A$3:$A$1025,MATCH($E4,学年度总表!$E$3:$E$1025,0))) -> 4 | B4: =IF(INDEX(学年度总表!$B$3:$B$1025,MATCH($E4,学年度总表!$E$3:$E$1025,0))="","",INDEX(学年度总表!$B$3:$B$1025,MATCH($E4,学年度总表!$E$3:$E$1025,0))) -> 2 | C4: =IF(INDEX(学年度总表!$C$3:$C$1025,MATCH($E4,学年度总表!$E$3:$E$1025,0))="","",INDEX(学年度总表!$C$3:$C$1025,MATCH($E4,学年度总表!$E$3:$E$1025,0))) -> 软工 | D4: =IF(INDEX(学年度总表!$D$3:$D$1025,MATCH($E4,学年度总表!$E$3:$E$1025,0))="","",INDEX(学年度总表!$D$3:$D$1025,MATCH($E4,学年度总表!$E$3:$E$1025,0))) -> 软工12班 | E4: 250451226 | F4: =IF(INDEX(学年度总表!$F$3:$F$1025,MATCH($E4,学年度总表!$E$3:$E$1025,0))="","",INDEX(学年度总表!$F$3:$F$1025,MATCH($E4,学年度总表!$E$3:$E$1025,0))) -> 刘航绮 | G4: =IF(INDEX(学年度总表!$G$3:$G$1025,MATCH($E4,学年度总表!$E$3:$E$1025,0))="","",INDEX(学年度总表!$G$3:$G$1025,MATCH($E4,学年度总表!$E$3:$E$1025,0))) -> 12.5 | H4: =IF(INDEX(学年度总表!$H$3:$H$1025,MATCH($E4,学年度总表!$E$3:$E$1025,0))="","",INDEX(学年度总表!$H$3:$H$1025,MATCH($E4,学年度总表!$E$3:$E$1025,0))) -> 69.19 | I4: =IF(INDEX(学年度总表!$I$3:$I$1025,MATCH($E4,学年度总表!$E$3:$E$1025,0))="","",INDEX(学年度总表!$I$3:$I$1025,MATCH($E4,学年度总表!$E$3:$E$1025,0))) -> 6.9 | J4: =IF(INDEX(学年度总表!$J$3:$J$1025,MATCH($E4,学年度总表!$E$3:$E$1025,0))="","",INDEX(学年度总表!$J$3:$J$1025,MATCH($E4,学年度总表!$E$3:$E$1025,0))) -> 88.59 | K4: =IF(INDEX(学年度总表!$K$3:$K$1025,MATCH($E4,学年度总表!$E$3:$E$1025,0))="","",INDEX(学年度总表!$K$3:$K$1025,MATCH($E4,学年度总表!$E$3:$E$1025,0))) -> 11 | L4: =IF(INDEX(学年度总表!$L$3:$L$1025,MATCH($E4,学年度总表!$E$3:$E$1025,0))="","",INDEX(学年度总表!$L$3:$L$1025,MATCH($E4,学年度总表!$E$3:$E$1025,0))) -> 70.12 | M4: =IF(INDEX(学年度总表!$M$3:$M$1025,MATCH($E4,学年度总表!$E$3:$E$1025,0))="","",INDEX(学年度总表!$M$3:$M$1025,MATCH($E4,学年度总表!$E$3:$E$1025,0))) -> 8.5 | N4: =IF(INDEX(学年度总表!$N$3:$N$1025,MATCH($E4,学年度总表!$E$3:$E$1025,0))="","",INDEX(学年度总表!$N$3:$N$1025,MATCH($E4,学年度总表!$E$3:$E$1025,0))) -> 89.62 | O4: =IF(INDEX(学年度总表!$O$3:$O$1025,MATCH($E4,学年度总表!$E$3:$E$1025,0))="","",INDEX(学年度总表!$O$3:$O$1025,MATCH($E4,学年度总表!$E$3:$E$1025,0))) -> 178.21 | P4: =IF(INDEX(学年度总表!$P$3:$P$1025,MATCH($E4,学年度总表!$E$3:$E$1025,0))="","",INDEX(学年度总表!$P$3:$P$1025,MATCH($E4,学年度总表!$E$3:$E$1025,0))) -> 省奖 | Q4: =IF(INDEX(学年度总表!$Q$3:$Q$1025,MATCH($E4,学年度总表!$E$3:$E$1025,0))="","",INDEX(学年度总表!$Q$3:$Q$1025,MATCH($E4,学年度总表!$E$3:$E$1025,0)))
A5: =IF(INDEX(学年度总表!$A$3:$A$1025,MATCH($E5,学年度总表!$E$3:$E$1025,0))="","",INDEX(学年度总表!$A$3:$A$1025,MATCH($E5,学年度总表!$E$3:$E$1025,0))) -> 5 | B5: =IF(INDEX(学年度总表!$B$3:$B$1025,MATCH($E5,学年度总表!$E$3:$E$1025,0))="","",INDEX(学年度总表!$B$3:$B$1025,MATCH($E5,学年度总表!$E$3:$E$1025,0))) -> 3 | C5: =IF(INDEX(学年度总表!$C$3:$C$1025,MATCH($E5,学年度总表!$E$3:$E$1025,0))="","",INDEX(学年度总表!$C$3:$C$1025,MATCH($E5,学年度总表!$E$3:$E$1025,0))) -> 软工 | D5: =IF(INDEX(学年度总表!$D$3:$D$1025,MATCH($E5,学年度总表!$E$3:$E$1025,0))="","",INDEX(学年度总表!$D$3:$D$1025,MATCH($E5,学年度总表!$E$3:$E$1025,0))) -> 软工9班 | E5: 250450916 | F5: =IF(INDEX(学年度总表!$F$3:$F$1025,MATCH($E5,学年度总表!$E$3:$E$1025,0))="","",INDEX(学年度总表!$F$3:$F$1025,MATCH($E5,学年度总表!$E$3:$E$1025,0))) -> 夏艺洋 | G5: =IF(INDEX(学年度总表!$G$3:$G$1025,MATCH($E5,学年度总表!$E$3:$E$1025,0))="","",INDEX(学年度总表!$G$3:$G$1025,MATCH($E5,学年度总表!$E$3:$E$1025,0))) -> 10.3 | H5: =IF(INDEX(学年度总表!$H$3:$H$1025,MATCH($E5,学年度总表!$E$3:$E$1025,0))="","",INDEX(学年度总表!$H$3:$H$1025,MATCH($E5,学年度总表!$E$3:$E$1025,0))) -> 75 | I5: =IF(INDEX(学年度总表!$I$3:$I$1025,MATCH($E5,学年度总表!$E$3:$E$1025,0))="","",INDEX(学年度总表!$I$3:$I$1025,MATCH($E5,学年度总表!$E$3:$E$1025,0))) -> 5.1 | J5: =IF(INDEX(学年度总表!$J$3:$J$1025,MATCH($E5,学年度总表!$E$3:$E$1025,0))="","",INDEX(学年度总表!$J$3:$J$1025,MATCH($E5,学年度总表!$E$3:$E$1025,0))) -> 90.4 | K5: =IF(INDEX(学年度总表!$K$3:$K$1025,MATCH($E5,学年度总表!$E$3:$E$1025,0))="","",INDEX(学年度总表!$K$3:$K$1025,MATCH($E5,学年度总表!$E$3:$E$1025,0))) -> 10.8 | L5: =IF(INDEX(学年度总表!$L$3:$L$1025,MATCH($E5,学年度总表!$E$3:$E$1025,0))="","",INDEX(学年度总表!$L$3:$L$1025,MATCH($E5,学年度总表!$E$3:$E$1025,0))) -> 70.45 | M5: =IF(INDEX(学年度总表!$M$3:$M$1025,MATCH($E5,学年度总表!$E$3:$E$1025,0))="","",INDEX(学年度总表!$M$3:$M$1025,MATCH($E5,学年度总表!$E$3:$E$1025,0))) -> 6.5 | N5: =IF(INDEX(学年度总表!$N$3:$N$1025,MATCH($E5,学年度总表!$E$3:$E$1025,0))="","",INDEX(学年度总表!$N$3:$N$1025,MATCH($E5,学年度总表!$E$3:$E$1025,0))) -> 87.75 | O5: =IF(INDEX(学年度总表!$O$3:$O$1025,MATCH($E5,学年度总表!$E$3:$E$1025,0))="","",INDEX(学年度总表!$O$3:$O$1025,MATCH($E5,学年度总表!$E$3:$E$1025,0))) -> 178.15 | P5: =IF(INDEX(学年度总表!$P$3:$P$1025,MATCH($E5,学年度总表!$E$3:$E$1025,0))="","",INDEX(学年度总表!$P$3:$P$1025,MATCH($E5,学年度总表!$E$3:$E$1025,0))) -> 校一等 | Q5: =IF(INDEX(学年度总表!$Q$3:$Q$1025,MATCH($E5,学年度总表!$E$3:$E$1025,0))="","",INDEX(学年度总表!$Q$3:$Q$1025,MATCH($E5,学年度总表!$E$3:$E$1025,0)))
A6: =IF(INDEX(学年度总表!$A$3:$A$1025,MATCH($E6,学年度总表!$E$3:$E$1025,0))="","",INDEX(学年度总表!$A$3:$A$1025,MATCH($E6,学年度总表!$E$3:$E$1025,0))) -> 6 | B6: =IF(INDEX(学年度总表!$B$3:$B$1025,MATCH($E6,学年度总表!$E$3:$E$1025,0))="","",INDEX(学年度总表!$B$3:$B$1025,MATCH($E6,学年度总表!$E$3:$E$1025,0))) -> 4 | C6: =IF(INDEX(学年度总表!$C$3:$C$1025,MATCH($E6,学年度总表!$E$3:$E$1025,0))="","",INDEX(学年度总表!$C$3:$C$1025,MATCH($E6,学年度总表!$E$3:$E$1025,0))) -> 软工 | D6: =IF(INDEX(学年度总表!$D$3:$D$1025,MATCH($E6,学年度总表!$E$3:$E$1025,0))="","",INDEX(学年度总表!$D$3:$D$1025,MATCH($E6,学年度总表!$E$3:$E$1025,0))) -> 软工13班 | E6: 250451316 | F6: =IF(INDEX(学年度总表!$F$3:$F$1025,MATCH($E6,学年度总表!$E$3:$E$1025,0))="","",INDEX(学年度总表!$F$3:$F$1025,MATCH($E6,学年度总表!$E$3:$E$1025,0))) -> 孙远骐 | G6: =IF(INDEX(学年度总表!$G$3:$G$1025,MATCH($E6,学年度总表!$E$3:$E$1025,0))="","",INDEX(学年度总表!$G$3:$G$1025,MATCH($E6,学年度总表!$E$3:$E$1025,0))) -> 10.6 | H6: =IF(INDEX(学年度总表!$H$3:$H$1025,MATCH($E6,学年度总表!$E$3:$E$1025,0))="","",INDEX(学年度总表!$H$3:$H$1025,MATCH($E6,学年度总表!$E$3:$E$1025,0))) -> 72.84 | I6: =IF(INDEX(学年度总表!$I$3:$I$1025,MATCH($E6,学年度总表!$E$3:$E$1025,0))="","",INDEX(学年度总表!$I$3:$I$1025,MATCH($E6,学年度总表!$E$3:$E$1025,0))) -> 5.2 | J6: =IF(INDEX(学年度总表!$J$3:$J$1025,MATCH($E6,学年度总表!$E$3:$E$1025,0))="","",INDEX(学年度总表!$J$3:$J$1025,MATCH($E6,学年度总表!$E$3:$E$1025,0))) -> 88.64 | K6: =IF(INDEX(学年度总表!$K$3:$K$1025,MATCH($E6,学年度总表!$E$3:$E$1025,0))="","",INDEX(学年度总表!$K$3:$K$1025,MATCH($E6,学年度总表!$E$3:$E$1025,0))) -> 10.8 | L6: =IF(INDEX(学年度总表!$L$3:$L$1025,MATCH($E6,学年度总表!$E$3:$E$1025,0))="","",INDEX(学年度总表!$L$3:$L$1025,MATCH($E6,学年度总表!$E$3:$E$1025,0))) -> 67.92 | M6: =IF(INDEX(学年度总表!$M$3:$M$1025,MATCH($E6,学年度总表!$E$3:$E$1025,0))="","",INDEX(学年度总表!$M$3:$M$1025,MATCH($E6,学年度总表!$E$3:$E$1025,0))) -> 6.85 | N6: =IF(INDEX(学年度总表!$N$3:$N$1025,MATCH($E6,学年度总表!$E$3:$E$1025,0))="","",INDEX(学年度总表!$N$3:$N$1025,MATCH($E6,学年度总表!$E$3:$E$1025,0))) -> 85.57 | O6: =IF(INDEX(学年度总表!$O$3:$O$1025,MATCH($E6,学年度总表!$E$3:$E$1025,0))="","",INDEX(学年度总表!$O$3:$O$1025,MATCH($E6,学年度总表!$E$3:$E$1025,0))) -> 174.21 | P6: =IF(INDEX(学年度总表!$P$3:$P$1025,MATCH($E6,学年度总表!$E$3:$E$1025,0))="","",INDEX(学年度总表!$P$3:$P$1025,MATCH($E6,学年度总表!$E$3:$E$1025,0))) -> 校一等 | Q6: =IF(INDEX(学年度总表!$Q$3:$Q$1025,MATCH($E6,学年度总表!$E$3:$E$1025,0))="","",INDEX(学年度总表!$Q$3:$Q$1025,MATCH($E6,学年度总表!$E$3:$E$1025,0)))
A7: =IF(INDEX(学年度总表!$A$3:$A$1025,MATCH($E7,学年度总表!$E$3:$E$1025,0))="","",INDEX(学年度总表!$A$3:$A$1025,MATCH($E7,学年度总表!$E$3:$E$1025,0))) -> 8 | B7: =IF(INDEX(学年度总表!$B$3:$B$1025,MATCH($E7,学年度总表!$E$3:$E$1025,0))="","",INDEX(学年度总表!$B$3:$B$1025,MATCH($E7,学年度总表!$E$3:$E$1025,0))) -> 5 | C7: =IF(INDEX(学年度总表!$C$3:$C$1025,MATCH($E7,学年度总表!$E$3:$E$1025,0))="","",INDEX(学年度总表!$C$3:$C$1025,MATCH($E7,学年度总表!$E$3:$E$1025,0))) -> 软工 | D7: =IF(INDEX(学年度总表!$D$3:$D$1025,MATCH($E7,学年度总表!$E$3:$E$1025,0))="","",INDEX(学年度总表!$D$3:$D$1025,MATCH($E7,学年度总表!$E$3:$E$1025,0))) -> 软工6班 | E7: 250450614 | F7: =IF(INDEX(学年度总表!$F$3:$F$1025,MATCH($E7,学年度总表!$E$3:$E$1025,0))="","",INDEX(学年度总表!$F$3:$F$1025,MATCH($E7,学年度总表!$E$3:$E$1025,0))) -> 陈韵竹 | G7: =IF(INDEX(学年度总表!$G$3:$G$1025,MATCH($E7,学年度总表!$E$3:$E$1025,0))="","",INDEX(学年度总表!$G$3:$G$1025,MATCH($E7,学年度总表!$E$3:$E$1025,0))) -> 11.6 | H7: =IF(INDEX(学年度总表!$H$3:$H$1025,MATCH($E7,学年度总表!$E$3:$E$1025,0))="","",INDEX(学年度总表!$H$3:$H$1025,MATCH($E7,学年度总表!$E$3:$E$1025,0))) -> 73.690909 | I7: =IF(INDEX(学年度总表!$I$3:$I$1025,MATCH($E7,学年度总表!$E$3:$E$1025,0))="","",INDEX(学年度总表!$I$3:$I$1025,MATCH($E7,学年度总表!$E$3:$E$1025,0))) -> 3.5 | J7: =IF(INDEX(学年度总表!$J$3:$J$1025,MATCH($E7,学年度总表!$E$3:$E$1025,0))="","",INDEX(学年度总表!$J$3:$J$1025,MATCH($E7,学年度总表!$E$3:$E$1025,0))) -> 88.79 | K7: =IF(INDEX(学年度总表!$K$3:$K$1025,MATCH($E7,学年度总表!$E$3:$E$1025,0))="","",INDEX(学年度总表!$K$3:$K$1025,MATCH($E7,学年度总表!$E$3:$E$1025,0))) -> 9.8 | L7: =IF(INDEX(学年度总表!$L$3:$L$1025,MATCH($E7,学年度总表!$E$3:$E$1025,0))="","",INDEX(学年度总表!$L$3:$L$1025,MATCH($E7,学年度总表!$E$3:$E$1025,0))) -> 70.43 | M7: =IF(INDEX(学年度总表!$M$3:$M$1025,MATCH($E7,学年度总表!$E$3:$E$1025,0))="","",INDEX(学年度总表!$M$3:$M$1025,MATCH($E7,学年度总表!$E$3:$E$1025,0))) -> 4.9 | N7: =IF(INDEX(学年度总表!$N$3:$N$1025,MATCH($E7,学年度总表!$E$3:$E$1025,0))="","",INDEX(学年度总表!$N$3:$N$1025,MATCH($E7,学年度总表!$E$3:$E$1025,0))) -> 85.13 | O7: =IF(INDEX(学年度总表!$O$3:$O$1025,MATCH($E7,学年度总表!$E$3:$E$1025,0))="","",INDEX(学年度总表!$O$3:$O$1025,MATCH($E7,学年度总表!$E$3:$E$1025,0))) -> 173.92 | P7: =IF(INDEX(学年度总表!$P$3:$P$1025,MATCH($E7,学年度总表!$E$3:$E$1025,0))="","",INDEX(学年度总表!$P$3:$P$1025,MATCH($E7,学年度总表!$E$3:$E$1025,0))) -> 校一等 | Q7: =IF(INDEX(学年度总表!$Q$3:$Q$1025,MATCH($E7,学年度总表!$E$3:$E$1025,0))="","",INDEX(学年度总表!$Q$3:$Q$1025,MATCH($E7,学年度总表!$E$3:$E$1025,0)))
A8: =IF(INDEX(学年度总表!$A$3:$A$1025,MATCH($E8,学年度总表!$E$3:$E$1025,0))="","",INDEX(学年度总表!$A$3:$A$1025,MATCH($E8,学年度总表!$E$3:$E$1025,0))) -> 15 | B8: =IF(INDEX(学年度总表!$B$3:$B$1025,MATCH($E8,学年度总表!$E$3:$E$1025,0))="","",INDEX(学年度总表!$B$3:$B$1025,MATCH($E8,学年度总表!$E$3:$E$1025,0))) -> 6 | C8: =IF(INDEX(学年度总表!$C$3:$C$1025,MATCH($E8,学年度总表!$E$3:$E$1025,0))="","",INDEX(学年度总表!$C$3:$C$1025,MATCH($E8,学年度总表!$E$3:$E$1025,0))) -> 软工 | D8: =IF(INDEX(学年度总表!$D$3:$D$1025,MATCH($E8,学年度总表!$E$3:$E$1025,0))="","",INDEX(学年度总表!$D$3:$D$1025,MATCH($E8,学年度总表!$E$3:$E$1025,0))) -> 软工14班 | E8: 250451405 | F8: =IF(INDEX(学年度总表!$F$3:$F$1025,MATCH($E8,学年度总表!$E$3:$E$1025,0))="","",INDEX(学年度总表!$F$3:$F$1025,MATCH($E8,学年度总表!$E$3:$E$1025,0))) -> 周梓锐 | G8: =IF(INDEX(学年度总表!$G$3:$G$1025,MATCH($E8,学年度总表!$E$3:$E$1025,0))="","",INDEX(学年度总表!$G$3:$G$1025,MATCH($E8,学年度总表!$E$3:$E$1025,0))) -> 11 | H8: =IF(INDEX(学年度总表!$H$3:$H$1025,MATCH($E8,学年度总表!$E$3:$E$1025,0))="","",INDEX(学年度总表!$H$3:$H$1025,MATCH($E8,学年度总表!$E$3:$E$1025,0))) -> 73.14 | I8: =IF(INDEX(学年度总表!$I$3:$I$1025,MATCH($E8,学年度总表!$E$3:$E$1025,0))="","",INDEX(学年度总表!$I$3:$I$1025,MATCH($E8,学年度总表!$E$3:$E$1025,0))) -> 3.8 | J8: =IF(INDEX(学年度总表!$J$3:$J$1025,MATCH($E8,学年度总表!$E$3:$E$1025,0))="","",INDEX(学年度总表!$J$3:$J$1025,MATCH($E8,学年度总表!$E$3:$E$1025,0))) -> 87.94 | K8: =IF(INDEX(学年度总表!$K$3:$K$1025,MATCH($E8,学年度总表!$E$3:$E$1025,0))="","",INDEX(学年度总表!$K$3:$K$1025,MATCH($E8,学年度总表!$E$3:$E$1025,0))) -> 10 | L8: =IF(INDEX(学年度总表!$L$3:$L$1025,MATCH($E8,学年度总表!$E$3:$E$1025,0))="","",INDEX(学年度总表!$L$3:$L$1025,MATCH($E8,学年度总表!$E$3:$E$1025,0))) -> 68.5 | M8: =IF(INDEX(学年度总表!$M$3:$M$1025,MATCH($E8,学年度总表!$E$3:$E$1025,0))="","",INDEX(学年度总表!$M$3:$M$1025,MATCH($E8,学年度总表!$E$3:$E$1025,0))) -> 4 | N8: =IF(INDEX(学年度总表!$N$3:$N$1025,MATCH($E8,学年度总表!$E$3:$E$1025,0))="","",INDEX(学年度总表!$N$3:$N$1025,MATCH($E8,学年度总表!$E$3:$E$1025,0))) -> 82.5 | O8: =IF(INDEX(学年度总表!$O$3:$O$1025,MATCH($E8,学年度总表!$E$3:$E$1025,0))="","",INDEX(学年度总表!$O$3:$O$1025,MATCH($E8,学年度总表!$E$3:$E$1025,0))) -> 170.44 | P8: =IF(INDEX(学年度总表!$P$3:$P$1025,MATCH($E8,学年度总表!$E$3:$E$1025,0))="","",INDEX(学年度总表!$P$3:$P$1025,MATCH($E8,学年度总表!$E$3:$E$1025,0))) -> 校一等 | Q8: =IF(INDEX(学年度总表!$Q$3:$Q$1025,MATCH($E8,学年度总表!$E$3:$E$1025,0))="","",INDEX(学年度总表!$Q$3:$Q$1025,MATCH($E8,学年度总表!$E$3:$E$1025,0)))
